WARNING:werkzeug: * Debugger is active!
INFO:werkzeug: * Debugger PIN: 444-631-731
INFO:werkzeug: * Detected change in '/media/khalil-gazairly/aser/ITI/Flask/flask_todo/todo/app.py', reloading
WARNING:werkzeug: * Debugger is active!
INFO:werkzeug: * Debugger PIN: 444-631-731
INFO:werkzeug: * Running on http://127.0.0.1:5000/ (Press CTRL+C to quit)
INFO:werkzeug: * Restarting with stat
WARNING:werkzeug: * Debugger is active!
INFO:werkzeug: * Debugger PIN: 444-631-731
INFO:werkzeug:127.0.0.1 - - [19/Nov/2021 19:24:17] "GET / HTTP/1.1" 200 -
INFO:werkzeug:127.0.0.1 - - [19/Nov/2021 19:24:32] "GET / HTTP/1.1" 200 -
INFO:werkzeug: * Detected change in '/media/khalil-gazairly/aser/ITI/Flask/flask_todo/todo/app.py', reloading
INFO:werkzeug: * Restarting with stat
2021-11-19 19:26:26,307 werkzeug - WARNING -  * Debugger is active!
2021-11-19 19:26:26,308 werkzeug - INFO -  * Debugger PIN: 444-631-731
2021-11-19 19:26:54,626 werkzeug - INFO -  * Detected change in '/media/khalil-gazairly/aser/ITI/Flask/flask_todo/todo/app.py', reloading
INFO:werkzeug: * Restarting with stat
19-Nov-21 werkzeug - WARNING -  * Debugger is active!
19-Nov-21 werkzeug - INFO -  * Debugger PIN: 444-631-731
19-Nov-21 werkzeug - INFO -  * Detected change in '/media/khalil-gazairly/aser/ITI/Flask/flask_todo/todo/app.py', reloading
INFO:werkzeug: * Restarting with stat
19-Nov-21 19:27:19 werkzeug - WARNING -  * Debugger is active!
19-Nov-21 19:27:19 werkzeug - INFO -  * Debugger PIN: 444-631-731
19-Nov-21 20:00:12 werkzeug - INFO -  * Detected change in '/media/khalil-gazairly/aser/ITI/Flask/flask_todo/todo/app.py', reloading
INFO:werkzeug: * Restarting with stat
19-Nov-21 20:00:14 werkzeug - WARNING -  * Debugger is active!
19-Nov-21 20:00:14 werkzeug - INFO -  * Debugger PIN: 444-631-731
19-Nov-21 20:00:23 werkzeug - INFO -  * Detected change in '/media/khalil-gazairly/aser/ITI/Flask/flask_todo/todo/app.py', reloading
INFO:werkzeug: * Restarting with stat
19-Nov-21 20:00:24 werkzeug - WARNING -  * Debugger is active!
19-Nov-21 20:00:24 werkzeug - INFO -  * Debugger PIN: 444-631-731
19-Nov-21 20:01:49 werkzeug - INFO -  * Detected change in '/media/khalil-gazairly/aser/ITI/Flask/flask_todo/todo/app.py', reloading
INFO:werkzeug: * Restarting with stat
19-Nov-21 20:01:52 werkzeug - WARNING -  * Debugger is active!
19-Nov-21 20:01:52 werkzeug - INFO -  * Debugger PIN: 444-631-731
19-Nov-21 20:30:53 werkzeug - INFO -  * Detected change in '/media/khalil-gazairly/aser/ITI/Flask/flask_todo/todo/app.py', reloading
INFO:werkzeug: * Restarting with stat
19-Nov-21 20:30:55 werkzeug - WARNING -  * Debugger is active!
19-Nov-21 20:30:55 werkzeug - INFO -  * Debugger PIN: 444-631-731
19-Nov-21 20:31:28 werkzeug - INFO -  * Detected change in '/media/khalil-gazairly/aser/ITI/Flask/flask_todo/todo/app.py', reloading
INFO:werkzeug: * Restarting with stat
19-Nov-21 20:31:28 werkzeug - WARNING -  * Debugger is active!
19-Nov-21 20:31:28 werkzeug - INFO -  * Debugger PIN: 444-631-731
19-Nov-21 20:32:24 werkzeug - INFO -  * Detected change in '/media/khalil-gazairly/aser/ITI/Flask/flask_todo/todo/app.py', reloading
INFO:werkzeug: * Restarting with stat
19-Nov-21 22:13:12 werkzeug - INFO -  * Running on http://127.0.0.1:5000/ (Press CTRL+C to quit)
19-Nov-21 22:13:12 werkzeug - INFO -  * Restarting with stat
19-Nov-21 22:13:12 werkzeug - WARNING -  * Debugger is active!
19-Nov-21 22:13:12 werkzeug - INFO -  * Debugger PIN: 444-631-731
19-Nov-21 22:13:18 werkzeug - INFO - 127.0.0.1 - - [19/Nov/2021 22:13:18] "GET /api/v1/todo HTTP/1.1" 200 -
19-Nov-21 22:14:02 werkzeug - INFO -  * Detected change in '/media/khalil-gazairly/aser/ITI/Flask/flask_todo/todo/app.py', reloading
19-Nov-21 22:14:02 werkzeug - INFO -  * Restarting with stat
19-Nov-21 22:14:03 werkzeug - WARNING -  * Debugger is active!
19-Nov-21 22:14:03 werkzeug - INFO -  * Debugger PIN: 444-631-731
19-Nov-21 22:14:07 werkzeug - INFO - 127.0.0.1 - - [19/Nov/2021 22:14:07] "GET /api/v1/todo HTTP/1.1" 200 -
19-Nov-21 22:14:22 werkzeug - INFO - 127.0.0.1 - - [19/Nov/2021 22:14:22] "GET /api/v1/todo?limit=1 HTTP/1.1" 200 -
19-Nov-21 22:14:28 werkzeug - INFO - 127.0.0.1 - - [19/Nov/2021 22:14:28] "GET /api/v1/todo?limit=2 HTTP/1.1" 200 -
19-Nov-21 22:18:28 werkzeug - INFO -  * Detected change in '/media/khalil-gazairly/aser/ITI/Flask/flask_todo/todo/app.py', reloading
19-Nov-21 22:18:28 werkzeug - INFO -  * Restarting with stat
19-Nov-21 22:18:28 werkzeug - WARNING -  * Debugger is active!
19-Nov-21 22:18:28 werkzeug - INFO -  * Debugger PIN: 444-631-731
19-Nov-21 22:18:55 werkzeug - INFO -  * Detected change in '/media/khalil-gazairly/aser/ITI/Flask/flask_todo/todo/app.py', reloading
19-Nov-21 22:18:55 werkzeug - INFO -  * Restarting with stat
19-Nov-21 22:18:56 werkzeug - WARNING -  * Debugger is active!
19-Nov-21 22:18:56 werkzeug - INFO -  * Debugger PIN: 444-631-731
19-Nov-21 22:18:59 werkzeug - INFO - 127.0.0.1 - - [19/Nov/2021 22:18:59] "GET /api/v1/todo?limit=2 HTTP/1.1" 200 -
19-Nov-21 22:20:18 werkzeug - INFO - 127.0.0.1 - - [19/Nov/2021 22:20:18] "[35m[1mPOST /api/v1/todo HTTP/1.1[0m" 201 -
19-Nov-21 22:21:04 werkzeug - INFO -  * Detected change in '/media/khalil-gazairly/aser/ITI/Flask/flask_todo/todo/app.py', reloading
19-Nov-21 22:21:04 werkzeug - INFO -  * Restarting with stat
19-Nov-21 22:21:04 werkzeug - WARNING -  * Debugger is active!
19-Nov-21 22:21:04 werkzeug - INFO -  * Debugger PIN: 444-631-731
19-Nov-21 22:21:09 werkzeug - INFO -  * Detected change in '/media/khalil-gazairly/aser/ITI/Flask/flask_todo/todo/app.py', reloading
19-Nov-21 22:21:09 werkzeug - INFO -  * Restarting with stat
19-Nov-21 22:21:09 werkzeug - WARNING -  * Debugger is active!
19-Nov-21 22:21:09 werkzeug - INFO -  * Debugger PIN: 444-631-731
19-Nov-21 22:21:30 werkzeug - INFO - 127.0.0.1 - - [19/Nov/2021 22:21:30] "[35m[1mPOST /api/v1/todo HTTP/1.1[0m" 201 -
19-Nov-21 22:21:37 werkzeug - INFO - 127.0.0.1 - - [19/Nov/2021 22:21:37] "[35m[1mPOST /api/v1/todo HTTP/1.1[0m" 201 -
19-Nov-21 22:24:15 werkzeug - INFO -  * Detected change in '/media/khalil-gazairly/aser/ITI/Flask/flask_todo/todo/app.py', reloading
19-Nov-21 22:24:16 werkzeug - INFO -  * Restarting with stat
19-Nov-21 22:24:16 werkzeug - WARNING -  * Debugger is active!
19-Nov-21 22:24:16 werkzeug - INFO -  * Debugger PIN: 444-631-731
19-Nov-21 22:24:21 werkzeug - INFO -  * Detected change in '/media/khalil-gazairly/aser/ITI/Flask/flask_todo/todo/app.py', reloading
19-Nov-21 22:24:21 werkzeug - INFO -  * Restarting with stat
19-Nov-21 22:24:22 werkzeug - WARNING -  * Debugger is active!
19-Nov-21 22:24:22 werkzeug - INFO -  * Debugger PIN: 444-631-731
19-Nov-21 22:24:24 werkzeug - INFO - 127.0.0.1 - - [19/Nov/2021 22:24:24] "[35m[1mPOST /api/v1/todo HTTP/1.1[0m" 500 -
19-Nov-21 22:24:32 werkzeug - INFO - 127.0.0.1 - - [19/Nov/2021 22:24:32] "[35m[1mPOST /api/v1/todo HTTP/1.1[0m" 500 -
19-Nov-21 22:25:56 werkzeug - INFO - 127.0.0.1 - - [19/Nov/2021 22:25:56] "[35m[1mPOST /api/v1/todo HTTP/1.1[0m" 500 -
19-Nov-21 22:26:29 werkzeug - INFO -  * Detected change in '/media/khalil-gazairly/aser/ITI/Flask/flask_todo/todo/app.py', reloading
19-Nov-21 22:26:29 werkzeug - INFO -  * Restarting with stat
19-Nov-21 22:26:30 werkzeug - WARNING -  * Debugger is active!
19-Nov-21 22:26:30 werkzeug - INFO -  * Debugger PIN: 444-631-731
19-Nov-21 22:26:58 werkzeug - INFO -  * Detected change in '/media/khalil-gazairly/aser/ITI/Flask/flask_todo/todo/app.py', reloading
19-Nov-21 22:26:58 werkzeug - INFO -  * Restarting with stat
19-Nov-21 22:26:58 werkzeug - WARNING -  * Debugger is active!
19-Nov-21 22:26:58 werkzeug - INFO -  * Debugger PIN: 444-631-731
19-Nov-21 22:27:01 werkzeug - INFO - 127.0.0.1 - - [19/Nov/2021 22:27:01] "[35m[1mPOST /api/v1/todo HTTP/1.1[0m" 500 -
19-Nov-21 22:27:10 werkzeug - INFO - 127.0.0.1 - - [19/Nov/2021 22:27:10] "[35m[1mPOST /api/v1/todo HTTP/1.1[0m" 500 -
19-Nov-21 22:28:26 werkzeug - INFO -  * Detected change in '/media/khalil-gazairly/aser/ITI/Flask/flask_todo/todo/app.py', reloading
19-Nov-21 22:28:26 werkzeug - INFO -  * Restarting with stat
19-Nov-21 22:28:26 werkzeug - WARNING -  * Debugger is active!
19-Nov-21 22:28:26 werkzeug - INFO -  * Debugger PIN: 444-631-731
19-Nov-21 22:28:27 werkzeug - INFO - 127.0.0.1 - - [19/Nov/2021 22:28:27] "[35m[1mPOST /api/v1/todo HTTP/1.1[0m" 500 -
19-Nov-21 22:29:46 werkzeug - INFO -  * Detected change in '/media/khalil-gazairly/aser/ITI/Flask/flask_todo/todo/app.py', reloading
19-Nov-21 22:29:46 werkzeug - INFO -  * Restarting with stat
19-Nov-21 22:29:46 werkzeug - WARNING -  * Debugger is active!
19-Nov-21 22:29:46 werkzeug - INFO -  * Debugger PIN: 444-631-731
19-Nov-21 22:29:51 app - ERROR - Exception on /api/v1/todo [POST]
Traceback (most recent call last):
  File "/media/khalil-gazairly/aser/ITI/Flask/flask_todo/todo/app.py", line 46, in post
    'test': request.form['test']
  File "/media/khalil-gazairly/aser/ITI/Flask/flask_todo/todo_env/lib/python3.8/site-packages/werkzeug/datastructures.py", line 377, in __getitem__
    raise exceptions.BadRequestKeyError(key)
werkzeug.exceptions.BadRequestKeyError: 400 Bad Request: The browser (or proxy) sent a request that this server could not understand.

During handling of the above exception, another exception occurred:

Traceback (most recent call last):
  File "/media/khalil-gazairly/aser/ITI/Flask/flask_todo/todo_env/lib/python3.8/site-packages/flask/app.py", line 1516, in full_dispatch_request
    rv = self.dispatch_request()
  File "/media/khalil-gazairly/aser/ITI/Flask/flask_todo/todo_env/lib/python3.8/site-packages/flask/app.py", line 1502, in dispatch_request
    return self.ensure_sync(self.view_functions[rule.endpoint])(**req.view_args)
  File "/media/khalil-gazairly/aser/ITI/Flask/flask_todo/todo_env/lib/python3.8/site-packages/flask_restful/__init__.py", line 467, in wrapper
    resp = resource(*args, **kwargs)
  File "/media/khalil-gazairly/aser/ITI/Flask/flask_todo/todo_env/lib/python3.8/site-packages/flask/views.py", line 84, in view
    return current_app.ensure_sync(self.dispatch_request)(*args, **kwargs)
  File "/media/khalil-gazairly/aser/ITI/Flask/flask_todo/todo_env/lib/python3.8/site-packages/flask_restful/__init__.py", line 582, in dispatch_request
    resp = meth(*args, **kwargs)
  File "/media/khalil-gazairly/aser/ITI/Flask/flask_todo/todo/app.py", line 52, in post
    abort(500)
  File "/media/khalil-gazairly/aser/ITI/Flask/flask_todo/todo_env/lib/python3.8/site-packages/werkzeug/exceptions.py", line 940, in abort
    _aborter(status, *args, **kwargs)
  File "/media/khalil-gazairly/aser/ITI/Flask/flask_todo/todo_env/lib/python3.8/site-packages/werkzeug/exceptions.py", line 923, in __call__
    raise self.mapping[code](*args, **kwargs)
werkzeug.exceptions.InternalServerError: 500 Internal Server Error: The server encountered an internal error and was unable to complete your request. Either the server is overloaded or there is an error in the application.
19-Nov-21 22:29:51 werkzeug - INFO - 127.0.0.1 - - [19/Nov/2021 22:29:51] "[35m[1mPOST /api/v1/todo HTTP/1.1[0m" 500 -
19-Nov-21 22:30:18 werkzeug - INFO -  * Running on http://127.0.0.1:5000/ (Press CTRL+C to quit)
19-Nov-21 22:30:18 werkzeug - INFO -  * Restarting with stat
19-Nov-21 22:30:18 werkzeug - WARNING -  * Debugger is active!
19-Nov-21 22:30:18 werkzeug - INFO -  * Debugger PIN: 444-631-731
19-Nov-21 22:30:21 app - ERROR - Exception on /api/v1/todo [POST]
Traceback (most recent call last):
  File "/media/khalil-gazairly/aser/ITI/Flask/flask_todo/todo/app.py", line 46, in post
    'test': request.form['test']
  File "/media/khalil-gazairly/aser/ITI/Flask/flask_todo/todo_env/lib/python3.8/site-packages/werkzeug/datastructures.py", line 377, in __getitem__
    raise exceptions.BadRequestKeyError(key)
werkzeug.exceptions.BadRequestKeyError: 400 Bad Request: The browser (or proxy) sent a request that this server could not understand.

During handling of the above exception, another exception occurred:

Traceback (most recent call last):
  File "/media/khalil-gazairly/aser/ITI/Flask/flask_todo/todo_env/lib/python3.8/site-packages/flask/app.py", line 1516, in full_dispatch_request
    rv = self.dispatch_request()
  File "/media/khalil-gazairly/aser/ITI/Flask/flask_todo/todo_env/lib/python3.8/site-packages/flask/app.py", line 1502, in dispatch_request
    return self.ensure_sync(self.view_functions[rule.endpoint])(**req.view_args)
  File "/media/khalil-gazairly/aser/ITI/Flask/flask_todo/todo_env/lib/python3.8/site-packages/flask_restful/__init__.py", line 467, in wrapper
    resp = resource(*args, **kwargs)
  File "/media/khalil-gazairly/aser/ITI/Flask/flask_todo/todo_env/lib/python3.8/site-packages/flask/views.py", line 84, in view
    return current_app.ensure_sync(self.dispatch_request)(*args, **kwargs)
  File "/media/khalil-gazairly/aser/ITI/Flask/flask_todo/todo_env/lib/python3.8/site-packages/flask_restful/__init__.py", line 582, in dispatch_request
    resp = meth(*args, **kwargs)
  File "/media/khalil-gazairly/aser/ITI/Flask/flask_todo/todo/app.py", line 52, in post
    abort(500)
  File "/media/khalil-gazairly/aser/ITI/Flask/flask_todo/todo_env/lib/python3.8/site-packages/werkzeug/exceptions.py", line 940, in abort
    _aborter(status, *args, **kwargs)
  File "/media/khalil-gazairly/aser/ITI/Flask/flask_todo/todo_env/lib/python3.8/site-packages/werkzeug/exceptions.py", line 923, in __call__
    raise self.mapping[code](*args, **kwargs)
werkzeug.exceptions.InternalServerError: 500 Internal Server Error: The server encountered an internal error and was unable to complete your request. Either the server is overloaded or there is an error in the application.
19-Nov-21 22:30:21 werkzeug - INFO - 127.0.0.1 - - [19/Nov/2021 22:30:21] "[35m[1mPOST /api/v1/todo HTTP/1.1[0m" 500 -
19-Nov-21 22:30:45 werkzeug - INFO -  * Detected change in '/media/khalil-gazairly/aser/ITI/Flask/flask_todo/todo/app.py', reloading
19-Nov-21 22:30:45 werkzeug - INFO -  * Restarting with stat
19-Nov-21 22:30:45 werkzeug - WARNING -  * Debugger is active!
19-Nov-21 22:30:45 werkzeug - INFO -  * Debugger PIN: 444-631-731
19-Nov-21 22:30:47 werkzeug - INFO - 127.0.0.1 - - [19/Nov/2021 22:30:47] "[35m[1mPOST /api/v1/todo HTTP/1.1[0m" 500 -
19-Nov-21 22:32:23 werkzeug - INFO -  * Detected change in '/media/khalil-gazairly/aser/ITI/Flask/flask_todo/todo/app.py', reloading
19-Nov-21 22:32:23 werkzeug - INFO -  * Restarting with stat
19-Nov-21 22:32:23 werkzeug - WARNING -  * Debugger is active!
19-Nov-21 22:32:23 werkzeug - INFO -  * Debugger PIN: 444-631-731
19-Nov-21 22:32:27 werkzeug - INFO - 127.0.0.1 - - [19/Nov/2021 22:32:27] "[35m[1mPOST /api/v1/todo HTTP/1.1[0m" 201 -
19-Nov-21 22:52:01 werkzeug - INFO -  * Detected change in '/media/khalil-gazairly/aser/ITI/Flask/flask_todo/todo/app.py', reloading
19-Nov-21 22:52:01 werkzeug - INFO -  * Restarting with stat
19-Nov-21 22:52:01 werkzeug - WARNING -  * Debugger is active!
19-Nov-21 22:52:01 werkzeug - INFO -  * Debugger PIN: 444-631-731
19-Nov-21 23:01:01 werkzeug - INFO -  * Detected change in '/media/khalil-gazairly/aser/ITI/Flask/flask_todo/todo/models.py', reloading
19-Nov-21 23:01:01 werkzeug - INFO -  * Restarting with stat
19-Nov-21 23:01:05 werkzeug - INFO -  * Running on http://127.0.0.1:5000/ (Press CTRL+C to quit)
19-Nov-21 23:01:05 werkzeug - INFO -  * Restarting with stat
19-Nov-21 23:01:05 werkzeug - WARNING -  * Debugger is active!
19-Nov-21 23:01:05 werkzeug - INFO -  * Debugger PIN: 444-631-731
19-Nov-21 23:01:42 werkzeug - INFO -  * Detected change in '/media/khalil-gazairly/aser/ITI/Flask/flask_todo/todo/models.py', reloading
19-Nov-21 23:01:42 werkzeug - INFO -  * Restarting with stat
19-Nov-21 23:01:43 werkzeug - WARNING -  * Debugger is active!
19-Nov-21 23:01:43 werkzeug - INFO -  * Debugger PIN: 444-631-731
19-Nov-21 23:02:35 werkzeug - INFO -  * Detected change in '/media/khalil-gazairly/aser/ITI/Flask/flask_todo/todo/models.py', reloading
19-Nov-21 23:02:35 werkzeug - INFO -  * Restarting with stat
19-Nov-21 23:02:35 werkzeug - WARNING -  * Debugger is active!
19-Nov-21 23:02:35 werkzeug - INFO -  * Debugger PIN: 444-631-731
19-Nov-21 23:03:22 werkzeug - INFO -  * Detected change in '/media/khalil-gazairly/aser/ITI/Flask/flask_todo/todo/models.py', reloading
19-Nov-21 23:03:22 werkzeug - INFO -  * Restarting with stat
19-Nov-21 23:03:23 werkzeug - WARNING -  * Debugger is active!
19-Nov-21 23:03:23 werkzeug - INFO -  * Debugger PIN: 444-631-731
19-Nov-21 23:14:40 werkzeug - INFO -  * Detected change in '/media/khalil-gazairly/aser/ITI/Flask/flask_todo/todo/models.py', reloading
19-Nov-21 23:14:41 werkzeug - INFO -  * Restarting with stat
19-Nov-21 23:14:41 werkzeug - WARNING -  * Debugger is active!
19-Nov-21 23:14:41 werkzeug - INFO -  * Debugger PIN: 444-631-731
19-Nov-21 23:24:07 werkzeug - INFO -  * Detected change in '/media/khalil-gazairly/aser/ITI/Flask/flask_todo/todo/models.py', reloading
19-Nov-21 23:24:08 werkzeug - INFO -  * Restarting with stat
19-Nov-21 23:24:08 werkzeug - WARNING -  * Debugger is active!
19-Nov-21 23:24:08 werkzeug - INFO -  * Debugger PIN: 444-631-731
19-Nov-21 23:27:14 werkzeug - INFO -  * Detected change in '/media/khalil-gazairly/aser/ITI/Flask/flask_todo/todo/app.py', reloading
19-Nov-21 23:27:14 werkzeug - INFO -  * Restarting with stat
19-Nov-21 23:27:16 werkzeug - WARNING -  * Debugger is active!
19-Nov-21 23:27:16 werkzeug - INFO -  * Debugger PIN: 444-631-731
19-Nov-21 23:27:48 werkzeug - INFO -  * Detected change in '/media/khalil-gazairly/aser/ITI/Flask/flask_todo/todo/app.py', reloading
19-Nov-21 23:27:48 werkzeug - INFO -  * Restarting with stat
19-Nov-21 23:27:49 werkzeug - WARNING -  * Debugger is active!
19-Nov-21 23:27:49 werkzeug - INFO -  * Debugger PIN: 444-631-731
19-Nov-21 23:28:22 werkzeug - INFO -  * Detected change in '/media/khalil-gazairly/aser/ITI/Flask/flask_todo/todo/app.py', reloading
19-Nov-21 23:28:22 werkzeug - INFO -  * Restarting with stat
19-Nov-21 23:28:23 werkzeug - WARNING -  * Debugger is active!
19-Nov-21 23:28:23 werkzeug - INFO -  * Debugger PIN: 444-631-731
19-Nov-21 23:29:31 werkzeug - INFO -  * Detected change in '/media/khalil-gazairly/aser/ITI/Flask/flask_todo/todo/app.py', reloading
19-Nov-21 23:29:31 werkzeug - INFO -  * Restarting with stat
19-Nov-21 23:29:32 werkzeug - WARNING -  * Debugger is active!
19-Nov-21 23:29:32 werkzeug - INFO -  * Debugger PIN: 444-631-731
19-Nov-21 23:32:02 werkzeug - INFO -  * Detected change in '/media/khalil-gazairly/aser/ITI/Flask/flask_todo/todo/app.py', reloading
19-Nov-21 23:32:03 werkzeug - INFO -  * Restarting with stat
19-Nov-21 23:32:31 werkzeug - INFO -  * Running on http://127.0.0.1:5000/ (Press CTRL+C to quit)
19-Nov-21 23:32:31 werkzeug - INFO -  * Restarting with stat
19-Nov-21 23:32:32 werkzeug - WARNING -  * Debugger is active!
19-Nov-21 23:32:32 werkzeug - INFO -  * Debugger PIN: 444-631-731
19-Nov-21 23:33:14 werkzeug - INFO -  * Detected change in '/media/khalil-gazairly/aser/ITI/Flask/flask_todo/todo/app.py', reloading
19-Nov-21 23:33:14 werkzeug - INFO -  * Restarting with stat
19-Nov-21 23:33:15 werkzeug - WARNING -  * Debugger is active!
19-Nov-21 23:33:15 werkzeug - INFO -  * Debugger PIN: 444-631-731
19-Nov-21 23:33:21 werkzeug - INFO -  * Running on http://127.0.0.1:5000/ (Press CTRL+C to quit)
19-Nov-21 23:33:21 werkzeug - INFO -  * Restarting with stat
19-Nov-21 23:33:21 werkzeug - WARNING -  * Debugger is active!
19-Nov-21 23:33:21 werkzeug - INFO -  * Debugger PIN: 444-631-731
19-Nov-21 23:37:01 werkzeug - INFO -  * Detected change in '/media/khalil-gazairly/aser/ITI/Flask/flask_todo/todo/app.py', reloading
19-Nov-21 23:37:01 werkzeug - INFO -  * Restarting with stat
19-Nov-21 23:37:04 werkzeug - WARNING -  * Debugger is active!
19-Nov-21 23:37:04 werkzeug - INFO -  * Debugger PIN: 444-631-731
19-Nov-21 23:37:34 werkzeug - INFO -  * Detected change in '/media/khalil-gazairly/aser/ITI/Flask/flask_todo/todo/app.py', reloading
19-Nov-21 23:37:34 werkzeug - INFO -  * Restarting with stat
19-Nov-21 23:37:35 werkzeug - WARNING -  * Debugger is active!
19-Nov-21 23:37:35 werkzeug - INFO -  * Debugger PIN: 444-631-731
19-Nov-21 23:38:26 werkzeug - INFO -  * Detected change in '/media/khalil-gazairly/aser/ITI/Flask/flask_todo/todo/app.py', reloading
19-Nov-21 23:38:26 werkzeug - INFO -  * Restarting with stat
19-Nov-21 23:38:26 werkzeug - WARNING -  * Debugger is active!
19-Nov-21 23:38:26 werkzeug - INFO -  * Debugger PIN: 444-631-731
19-Nov-21 23:39:29 werkzeug - INFO -  * Detected change in '/media/khalil-gazairly/aser/ITI/Flask/flask_todo/todo/app.py', reloading
19-Nov-21 23:39:30 werkzeug - INFO -  * Restarting with stat
19-Nov-21 23:39:31 werkzeug - WARNING -  * Debugger is active!
19-Nov-21 23:39:31 werkzeug - INFO -  * Debugger PIN: 444-631-731
19-Nov-21 23:40:19 werkzeug - INFO -  * Detected change in '/media/khalil-gazairly/aser/ITI/Flask/flask_todo/todo/models.py', reloading
19-Nov-21 23:40:19 werkzeug - INFO -  * Restarting with stat
19-Nov-21 23:49:57 werkzeug - INFO -  * Running on http://127.0.0.1:5000/ (Press CTRL+C to quit)
19-Nov-21 23:49:57 werkzeug - INFO -  * Restarting with stat
19-Nov-21 23:50:04 werkzeug - WARNING -  * Debugger is active!
19-Nov-21 23:50:04 werkzeug - INFO -  * Debugger PIN: 444-631-731
19-Nov-21 23:52:59 werkzeug - INFO - 127.0.0.1 - - [19/Nov/2021 23:52:59] "[35m[1mPOST /api/v1/todo HTTP/1.1[0m" 500 -
19-Nov-21 23:53:01 werkzeug - INFO -  * Detected change in '/media/khalil-gazairly/aser/ITI/Flask/flask_todo/todo/app.py', reloading
19-Nov-21 23:53:01 werkzeug - INFO -  * Restarting with stat
19-Nov-21 23:57:54 werkzeug - INFO -  * Running on http://127.0.0.1:5000/ (Press CTRL+C to quit)
19-Nov-21 23:57:54 werkzeug - INFO -  * Restarting with stat
19-Nov-21 23:57:55 werkzeug - WARNING -  * Debugger is active!
19-Nov-21 23:57:55 werkzeug - INFO -  * Debugger PIN: 444-631-731
19-Nov-21 23:57:58 werkzeug - INFO - 127.0.0.1 - - [19/Nov/2021 23:57:58] "[35m[1mPOST /api/v1/todo HTTP/1.1[0m" 500 -
19-Nov-21 23:58:29 werkzeug - INFO - 127.0.0.1 - - [19/Nov/2021 23:58:29] "[35m[1mPOST /api/v1/todo HTTP/1.1[0m" 500 -
19-Nov-21 23:58:51 werkzeug - INFO -  * Detected change in '/media/khalil-gazairly/aser/ITI/Flask/flask_todo/todo/app.py', reloading
19-Nov-21 23:58:51 werkzeug - INFO -  * Restarting with stat
19-Nov-21 23:58:54 werkzeug - WARNING -  * Debugger is active!
19-Nov-21 23:58:54 werkzeug - INFO -  * Debugger PIN: 444-631-731
19-Nov-21 23:58:55 werkzeug - INFO - 127.0.0.1 - - [19/Nov/2021 23:58:55] "[35m[1mPOST /api/v1/todo HTTP/1.1[0m" 500 -
19-Nov-21 23:59:05 werkzeug - INFO - 127.0.0.1 - - [19/Nov/2021 23:59:05] "[35m[1mGET /api/v1/todo HTTP/1.1[0m" 500 -
20-Nov-21 00:00:32 werkzeug - INFO -  * Detected change in '/media/khalil-gazairly/aser/ITI/Flask/flask_todo/todo/app.py', reloading
20-Nov-21 00:00:32 werkzeug - INFO -  * Restarting with stat
20-Nov-21 00:00:35 werkzeug - WARNING -  * Debugger is active!
20-Nov-21 00:00:35 werkzeug - INFO -  * Debugger PIN: 444-631-731
20-Nov-21 00:00:54 werkzeug - INFO -  * Detected change in '/media/khalil-gazairly/aser/ITI/Flask/flask_todo/todo/app.py', reloading
20-Nov-21 00:00:54 werkzeug - INFO -  * Restarting with stat
20-Nov-21 00:00:55 werkzeug - WARNING -  * Debugger is active!
20-Nov-21 00:00:55 werkzeug - INFO -  * Debugger PIN: 444-631-731
20-Nov-21 00:00:57 werkzeug - INFO - 127.0.0.1 - - [20/Nov/2021 00:00:57] "[35m[1mGET /api/v1/todo HTTP/1.1[0m" 500 -
20-Nov-21 00:02:04 werkzeug - INFO -  * Detected change in '/media/khalil-gazairly/aser/ITI/Flask/flask_todo/todo/app.py', reloading
20-Nov-21 00:02:04 werkzeug - INFO -  * Restarting with stat
20-Nov-21 00:02:06 werkzeug - WARNING -  * Debugger is active!
20-Nov-21 00:02:06 werkzeug - INFO -  * Debugger PIN: 444-631-731
20-Nov-21 00:02:06 werkzeug - INFO - 127.0.0.1 - - [20/Nov/2021 00:02:06] "[35m[1mGET /api/v1/todo HTTP/1.1[0m" 500 -
20-Nov-21 00:02:29 werkzeug - INFO - 127.0.0.1 - - [20/Nov/2021 00:02:29] "[35m[1mGET /api/v1/todo HTTP/1.1[0m" 500 -
20-Nov-21 00:04:14 werkzeug - INFO -  * Detected change in '/media/khalil-gazairly/aser/ITI/Flask/flask_todo/todo/app.py', reloading
20-Nov-21 00:04:14 werkzeug - INFO -  * Restarting with stat
20-Nov-21 00:04:16 werkzeug - WARNING -  * Debugger is active!
20-Nov-21 00:04:16 werkzeug - INFO -  * Debugger PIN: 444-631-731
20-Nov-21 00:04:21 app - ERROR - Exception on /api/v1/todo [GET]
Traceback (most recent call last):
  File "/media/khalil-gazairly/aser/ITI/Flask/flask_todo/todo/app.py", line 78, in get
    my_new_list.append(data)
UnboundLocalError: local variable 'data' referenced before assignment

During handling of the above exception, another exception occurred:

Traceback (most recent call last):
  File "/media/khalil-gazairly/aser/ITI/Flask/flask_todo/todo_env/lib/python3.8/site-packages/flask/app.py", line 1516, in full_dispatch_request
    rv = self.dispatch_request()
  File "/media/khalil-gazairly/aser/ITI/Flask/flask_todo/todo_env/lib/python3.8/site-packages/flask/app.py", line 1502, in dispatch_request
    return self.ensure_sync(self.view_functions[rule.endpoint])(**req.view_args)
  File "/media/khalil-gazairly/aser/ITI/Flask/flask_todo/todo_env/lib/python3.8/site-packages/flask_restful/__init__.py", line 467, in wrapper
    resp = resource(*args, **kwargs)
  File "/media/khalil-gazairly/aser/ITI/Flask/flask_todo/todo_env/lib/python3.8/site-packages/flask/views.py", line 84, in view
    return current_app.ensure_sync(self.dispatch_request)(*args, **kwargs)
  File "/media/khalil-gazairly/aser/ITI/Flask/flask_todo/todo_env/lib/python3.8/site-packages/flask_restful/__init__.py", line 582, in dispatch_request
    resp = meth(*args, **kwargs)
  File "/media/khalil-gazairly/aser/ITI/Flask/flask_todo/todo/app.py", line 86, in get
    abort(500, message="Internal Server Error {}".format(e))
  File "/media/khalil-gazairly/aser/ITI/Flask/flask_todo/todo_env/lib/python3.8/site-packages/flask_restful/__init__.py", line 31, in abort
    original_flask_abort(http_status_code)
  File "/media/khalil-gazairly/aser/ITI/Flask/flask_todo/todo_env/lib/python3.8/site-packages/werkzeug/exceptions.py", line 940, in abort
    _aborter(status, *args, **kwargs)
  File "/media/khalil-gazairly/aser/ITI/Flask/flask_todo/todo_env/lib/python3.8/site-packages/werkzeug/exceptions.py", line 923, in __call__
    raise self.mapping[code](*args, **kwargs)
werkzeug.exceptions.InternalServerError: 500 Internal Server Error: The server encountered an internal error and was unable to complete your request. Either the server is overloaded or there is an error in the application.
20-Nov-21 00:04:21 werkzeug - INFO - 127.0.0.1 - - [20/Nov/2021 00:04:21] "[35m[1mGET /api/v1/todo HTTP/1.1[0m" 500 -
20-Nov-21 00:05:02 werkzeug - INFO -  * Running on http://127.0.0.1:5000/ (Press CTRL+C to quit)
20-Nov-21 00:05:02 werkzeug - INFO -  * Restarting with stat
20-Nov-21 00:05:03 werkzeug - WARNING -  * Debugger is active!
20-Nov-21 00:05:03 werkzeug - INFO -  * Debugger PIN: 444-631-731
20-Nov-21 00:05:14 app - ERROR - Exception on /api/v1/todo [GET]
Traceback (most recent call last):
  File "/media/khalil-gazairly/aser/ITI/Flask/flask_todo/todo/app.py", line 78, in get
    my_new_list.append(data)
UnboundLocalError: local variable 'data' referenced before assignment

During handling of the above exception, another exception occurred:

Traceback (most recent call last):
  File "/media/khalil-gazairly/aser/ITI/Flask/flask_todo/todo_env/lib/python3.8/site-packages/flask/app.py", line 1516, in full_dispatch_request
    rv = self.dispatch_request()
  File "/media/khalil-gazairly/aser/ITI/Flask/flask_todo/todo_env/lib/python3.8/site-packages/flask/app.py", line 1502, in dispatch_request
    return self.ensure_sync(self.view_functions[rule.endpoint])(**req.view_args)
  File "/media/khalil-gazairly/aser/ITI/Flask/flask_todo/todo_env/lib/python3.8/site-packages/flask_restful/__init__.py", line 467, in wrapper
    resp = resource(*args, **kwargs)
  File "/media/khalil-gazairly/aser/ITI/Flask/flask_todo/todo_env/lib/python3.8/site-packages/flask/views.py", line 84, in view
    return current_app.ensure_sync(self.dispatch_request)(*args, **kwargs)
  File "/media/khalil-gazairly/aser/ITI/Flask/flask_todo/todo_env/lib/python3.8/site-packages/flask_restful/__init__.py", line 582, in dispatch_request
    resp = meth(*args, **kwargs)
  File "/media/khalil-gazairly/aser/ITI/Flask/flask_todo/todo/app.py", line 86, in get
    abort(500, message="Internal Server Error {}".format(e))
  File "/media/khalil-gazairly/aser/ITI/Flask/flask_todo/todo_env/lib/python3.8/site-packages/flask_restful/__init__.py", line 31, in abort
    original_flask_abort(http_status_code)
  File "/media/khalil-gazairly/aser/ITI/Flask/flask_todo/todo_env/lib/python3.8/site-packages/werkzeug/exceptions.py", line 940, in abort
    _aborter(status, *args, **kwargs)
  File "/media/khalil-gazairly/aser/ITI/Flask/flask_todo/todo_env/lib/python3.8/site-packages/werkzeug/exceptions.py", line 923, in __call__
    raise self.mapping[code](*args, **kwargs)
werkzeug.exceptions.InternalServerError: 500 Internal Server Error: The server encountered an internal error and was unable to complete your request. Either the server is overloaded or there is an error in the application.
20-Nov-21 00:05:14 werkzeug - INFO - 127.0.0.1 - - [20/Nov/2021 00:05:14] "[35m[1mGET /api/v1/todo HTTP/1.1[0m" 500 -
20-Nov-21 00:05:18 app - ERROR - Exception on /api/v1/todo [POST]
Traceback (most recent call last):
  File "/media/khalil-gazairly/aser/ITI/Flask/flask_todo/todo_env/lib/python3.8/site-packages/sqlalchemy/engine/base.py", line 1802, in _execute_context
    self.dialect.do_execute(
  File "/media/khalil-gazairly/aser/ITI/Flask/flask_todo/todo_env/lib/python3.8/site-packages/sqlalchemy/engine/default.py", line 719, in do_execute
    cursor.execute(statement, parameters)
sqlite3.IntegrityError: NOT NULL constraint failed: todo.name

The above exception was the direct cause of the following exception:

Traceback (most recent call last):
  File "/media/khalil-gazairly/aser/ITI/Flask/flask_todo/todo/app.py", line 51, in post
    db.session.commit()  # commit to db
  File "<string>", line 2, in commit
  File "/media/khalil-gazairly/aser/ITI/Flask/flask_todo/todo_env/lib/python3.8/site-packages/sqlalchemy/orm/session.py", line 1428, in commit
    self._transaction.commit(_to_root=self.future)
  File "/media/khalil-gazairly/aser/ITI/Flask/flask_todo/todo_env/lib/python3.8/site-packages/sqlalchemy/orm/session.py", line 829, in commit
    self._prepare_impl()
  File "/media/khalil-gazairly/aser/ITI/Flask/flask_todo/todo_env/lib/python3.8/site-packages/sqlalchemy/orm/session.py", line 808, in _prepare_impl
    self.session.flush()
  File "/media/khalil-gazairly/aser/ITI/Flask/flask_todo/todo_env/lib/python3.8/site-packages/sqlalchemy/orm/session.py", line 3345, in flush
    self._flush(objects)
  File "/media/khalil-gazairly/aser/ITI/Flask/flask_todo/todo_env/lib/python3.8/site-packages/sqlalchemy/orm/session.py", line 3485, in _flush
    transaction.rollback(_capture_exception=True)
  File "/media/khalil-gazairly/aser/ITI/Flask/flask_todo/todo_env/lib/python3.8/site-packages/sqlalchemy/util/langhelpers.py", line 70, in __exit__
    compat.raise_(
  File "/media/khalil-gazairly/aser/ITI/Flask/flask_todo/todo_env/lib/python3.8/site-packages/sqlalchemy/util/compat.py", line 207, in raise_
    raise exception
  File "/media/khalil-gazairly/aser/ITI/Flask/flask_todo/todo_env/lib/python3.8/site-packages/sqlalchemy/orm/session.py", line 3445, in _flush
    flush_context.execute()
  File "/media/khalil-gazairly/aser/ITI/Flask/flask_todo/todo_env/lib/python3.8/site-packages/sqlalchemy/orm/unitofwork.py", line 456, in execute
    rec.execute(self)
  File "/media/khalil-gazairly/aser/ITI/Flask/flask_todo/todo_env/lib/python3.8/site-packages/sqlalchemy/orm/unitofwork.py", line 630, in execute
    util.preloaded.orm_persistence.save_obj(
  File "/media/khalil-gazairly/aser/ITI/Flask/flask_todo/todo_env/lib/python3.8/site-packages/sqlalchemy/orm/persistence.py", line 244, in save_obj
    _emit_insert_statements(
  File "/media/khalil-gazairly/aser/ITI/Flask/flask_todo/todo_env/lib/python3.8/site-packages/sqlalchemy/orm/persistence.py", line 1221, in _emit_insert_statements
    result = connection._execute_20(
  File "/media/khalil-gazairly/aser/ITI/Flask/flask_todo/todo_env/lib/python3.8/site-packages/sqlalchemy/engine/base.py", line 1614, in _execute_20
    return meth(self, args_10style, kwargs_10style, execution_options)
  File "/media/khalil-gazairly/aser/ITI/Flask/flask_todo/todo_env/lib/python3.8/site-packages/sqlalchemy/sql/elements.py", line 325, in _execute_on_connection
    return connection._execute_clauseelement(
  File "/media/khalil-gazairly/aser/ITI/Flask/flask_todo/todo_env/lib/python3.8/site-packages/sqlalchemy/engine/base.py", line 1481, in _execute_clauseelement
    ret = self._execute_context(
  File "/media/khalil-gazairly/aser/ITI/Flask/flask_todo/todo_env/lib/python3.8/site-packages/sqlalchemy/engine/base.py", line 1845, in _execute_context
    self._handle_dbapi_exception(
  File "/media/khalil-gazairly/aser/ITI/Flask/flask_todo/todo_env/lib/python3.8/site-packages/sqlalchemy/engine/base.py", line 2026, in _handle_dbapi_exception
    util.raise_(
  File "/media/khalil-gazairly/aser/ITI/Flask/flask_todo/todo_env/lib/python3.8/site-packages/sqlalchemy/util/compat.py", line 207, in raise_
    raise exception
  File "/media/khalil-gazairly/aser/ITI/Flask/flask_todo/todo_env/lib/python3.8/site-packages/sqlalchemy/engine/base.py", line 1802, in _execute_context
    self.dialect.do_execute(
  File "/media/khalil-gazairly/aser/ITI/Flask/flask_todo/todo_env/lib/python3.8/site-packages/sqlalchemy/engine/default.py", line 719, in do_execute
    cursor.execute(statement, parameters)
sqlalchemy.exc.IntegrityError: (sqlite3.IntegrityError) NOT NULL constraint failed: todo.name
[SQL: INSERT INTO todo (name, priority, description, finished, created_at) VALUES (?, ?, ?, ?, ?)]
[parameters: (None, None, None, None, '2021-11-20 00:05:18.668354')]
(Background on this error at: https://sqlalche.me/e/14/gkpj)

During handling of the above exception, another exception occurred:

Traceback (most recent call last):
  File "/media/khalil-gazairly/aser/ITI/Flask/flask_todo/todo_env/lib/python3.8/site-packages/flask/app.py", line 1516, in full_dispatch_request
    rv = self.dispatch_request()
  File "/media/khalil-gazairly/aser/ITI/Flask/flask_todo/todo_env/lib/python3.8/site-packages/flask/app.py", line 1502, in dispatch_request
    return self.ensure_sync(self.view_functions[rule.endpoint])(**req.view_args)
  File "/media/khalil-gazairly/aser/ITI/Flask/flask_todo/todo_env/lib/python3.8/site-packages/flask_restful/__init__.py", line 467, in wrapper
    resp = resource(*args, **kwargs)
  File "/media/khalil-gazairly/aser/ITI/Flask/flask_todo/todo_env/lib/python3.8/site-packages/flask/views.py", line 84, in view
    return current_app.ensure_sync(self.dispatch_request)(*args, **kwargs)
  File "/media/khalil-gazairly/aser/ITI/Flask/flask_todo/todo_env/lib/python3.8/site-packages/flask_restful/__init__.py", line 582, in dispatch_request
    resp = meth(*args, **kwargs)
  File "/media/khalil-gazairly/aser/ITI/Flask/flask_todo/todo/app.py", line 56, in post
    abort(500, message='Internal Server Error')
  File "/media/khalil-gazairly/aser/ITI/Flask/flask_todo/todo_env/lib/python3.8/site-packages/flask_restful/__init__.py", line 31, in abort
    original_flask_abort(http_status_code)
  File "/media/khalil-gazairly/aser/ITI/Flask/flask_todo/todo_env/lib/python3.8/site-packages/werkzeug/exceptions.py", line 940, in abort
    _aborter(status, *args, **kwargs)
  File "/media/khalil-gazairly/aser/ITI/Flask/flask_todo/todo_env/lib/python3.8/site-packages/werkzeug/exceptions.py", line 923, in __call__
    raise self.mapping[code](*args, **kwargs)
werkzeug.exceptions.InternalServerError: 500 Internal Server Error: The server encountered an internal error and was unable to complete your request. Either the server is overloaded or there is an error in the application.
20-Nov-21 00:05:18 werkzeug - INFO - 127.0.0.1 - - [20/Nov/2021 00:05:18] "[35m[1mPOST /api/v1/todo HTTP/1.1[0m" 500 -
20-Nov-21 00:07:02 werkzeug - INFO -  * Detected change in '/media/khalil-gazairly/aser/ITI/Flask/flask_todo/todo/app.py', reloading
20-Nov-21 00:07:02 werkzeug - INFO -  * Restarting with stat
20-Nov-21 00:07:06 werkzeug - WARNING -  * Debugger is active!
20-Nov-21 00:07:06 werkzeug - INFO -  * Debugger PIN: 444-631-731
20-Nov-21 00:07:07 app - ERROR - Exception on /api/v1/todo [POST]
Traceback (most recent call last):
  File "/media/khalil-gazairly/aser/ITI/Flask/flask_todo/todo_env/lib/python3.8/site-packages/sqlalchemy/engine/base.py", line 1802, in _execute_context
    self.dialect.do_execute(
  File "/media/khalil-gazairly/aser/ITI/Flask/flask_todo/todo_env/lib/python3.8/site-packages/sqlalchemy/engine/default.py", line 719, in do_execute
    cursor.execute(statement, parameters)
sqlite3.IntegrityError: NOT NULL constraint failed: todo.name

The above exception was the direct cause of the following exception:

Traceback (most recent call last):
  File "/media/khalil-gazairly/aser/ITI/Flask/flask_todo/todo/app.py", line 51, in post
    db.session.commit()  # commit to db
  File "<string>", line 2, in commit
  File "/media/khalil-gazairly/aser/ITI/Flask/flask_todo/todo_env/lib/python3.8/site-packages/sqlalchemy/orm/session.py", line 1428, in commit
    self._transaction.commit(_to_root=self.future)
  File "/media/khalil-gazairly/aser/ITI/Flask/flask_todo/todo_env/lib/python3.8/site-packages/sqlalchemy/orm/session.py", line 829, in commit
    self._prepare_impl()
  File "/media/khalil-gazairly/aser/ITI/Flask/flask_todo/todo_env/lib/python3.8/site-packages/sqlalchemy/orm/session.py", line 808, in _prepare_impl
    self.session.flush()
  File "/media/khalil-gazairly/aser/ITI/Flask/flask_todo/todo_env/lib/python3.8/site-packages/sqlalchemy/orm/session.py", line 3345, in flush
    self._flush(objects)
  File "/media/khalil-gazairly/aser/ITI/Flask/flask_todo/todo_env/lib/python3.8/site-packages/sqlalchemy/orm/session.py", line 3485, in _flush
    transaction.rollback(_capture_exception=True)
  File "/media/khalil-gazairly/aser/ITI/Flask/flask_todo/todo_env/lib/python3.8/site-packages/sqlalchemy/util/langhelpers.py", line 70, in __exit__
    compat.raise_(
  File "/media/khalil-gazairly/aser/ITI/Flask/flask_todo/todo_env/lib/python3.8/site-packages/sqlalchemy/util/compat.py", line 207, in raise_
    raise exception
  File "/media/khalil-gazairly/aser/ITI/Flask/flask_todo/todo_env/lib/python3.8/site-packages/sqlalchemy/orm/session.py", line 3445, in _flush
    flush_context.execute()
  File "/media/khalil-gazairly/aser/ITI/Flask/flask_todo/todo_env/lib/python3.8/site-packages/sqlalchemy/orm/unitofwork.py", line 456, in execute
    rec.execute(self)
  File "/media/khalil-gazairly/aser/ITI/Flask/flask_todo/todo_env/lib/python3.8/site-packages/sqlalchemy/orm/unitofwork.py", line 630, in execute
    util.preloaded.orm_persistence.save_obj(
  File "/media/khalil-gazairly/aser/ITI/Flask/flask_todo/todo_env/lib/python3.8/site-packages/sqlalchemy/orm/persistence.py", line 244, in save_obj
    _emit_insert_statements(
  File "/media/khalil-gazairly/aser/ITI/Flask/flask_todo/todo_env/lib/python3.8/site-packages/sqlalchemy/orm/persistence.py", line 1221, in _emit_insert_statements
    result = connection._execute_20(
  File "/media/khalil-gazairly/aser/ITI/Flask/flask_todo/todo_env/lib/python3.8/site-packages/sqlalchemy/engine/base.py", line 1614, in _execute_20
    return meth(self, args_10style, kwargs_10style, execution_options)
  File "/media/khalil-gazairly/aser/ITI/Flask/flask_todo/todo_env/lib/python3.8/site-packages/sqlalchemy/sql/elements.py", line 325, in _execute_on_connection
    return connection._execute_clauseelement(
  File "/media/khalil-gazairly/aser/ITI/Flask/flask_todo/todo_env/lib/python3.8/site-packages/sqlalchemy/engine/base.py", line 1481, in _execute_clauseelement
    ret = self._execute_context(
  File "/media/khalil-gazairly/aser/ITI/Flask/flask_todo/todo_env/lib/python3.8/site-packages/sqlalchemy/engine/base.py", line 1845, in _execute_context
    self._handle_dbapi_exception(
  File "/media/khalil-gazairly/aser/ITI/Flask/flask_todo/todo_env/lib/python3.8/site-packages/sqlalchemy/engine/base.py", line 2026, in _handle_dbapi_exception
    util.raise_(
  File "/media/khalil-gazairly/aser/ITI/Flask/flask_todo/todo_env/lib/python3.8/site-packages/sqlalchemy/util/compat.py", line 207, in raise_
    raise exception
  File "/media/khalil-gazairly/aser/ITI/Flask/flask_todo/todo_env/lib/python3.8/site-packages/sqlalchemy/engine/base.py", line 1802, in _execute_context
    self.dialect.do_execute(
  File "/media/khalil-gazairly/aser/ITI/Flask/flask_todo/todo_env/lib/python3.8/site-packages/sqlalchemy/engine/default.py", line 719, in do_execute
    cursor.execute(statement, parameters)
sqlalchemy.exc.IntegrityError: (sqlite3.IntegrityError) NOT NULL constraint failed: todo.name
[SQL: INSERT INTO todo (name, priority, description, finished, created_at) VALUES (?, ?, ?, ?, ?)]
[parameters: (None, None, None, None, '2021-11-20 00:07:07.323605')]
(Background on this error at: https://sqlalche.me/e/14/gkpj)

During handling of the above exception, another exception occurred:

Traceback (most recent call last):
  File "/media/khalil-gazairly/aser/ITI/Flask/flask_todo/todo_env/lib/python3.8/site-packages/flask/app.py", line 1516, in full_dispatch_request
    rv = self.dispatch_request()
  File "/media/khalil-gazairly/aser/ITI/Flask/flask_todo/todo_env/lib/python3.8/site-packages/flask/app.py", line 1502, in dispatch_request
    return self.ensure_sync(self.view_functions[rule.endpoint])(**req.view_args)
  File "/media/khalil-gazairly/aser/ITI/Flask/flask_todo/todo_env/lib/python3.8/site-packages/flask_restful/__init__.py", line 467, in wrapper
    resp = resource(*args, **kwargs)
  File "/media/khalil-gazairly/aser/ITI/Flask/flask_todo/todo_env/lib/python3.8/site-packages/flask/views.py", line 84, in view
    return current_app.ensure_sync(self.dispatch_request)(*args, **kwargs)
  File "/media/khalil-gazairly/aser/ITI/Flask/flask_todo/todo_env/lib/python3.8/site-packages/flask_restful/__init__.py", line 582, in dispatch_request
    resp = meth(*args, **kwargs)
  File "/media/khalil-gazairly/aser/ITI/Flask/flask_todo/todo/app.py", line 56, in post
    abort(500, message='Internal Server Error')
  File "/media/khalil-gazairly/aser/ITI/Flask/flask_todo/todo_env/lib/python3.8/site-packages/flask_restful/__init__.py", line 31, in abort
    original_flask_abort(http_status_code)
  File "/media/khalil-gazairly/aser/ITI/Flask/flask_todo/todo_env/lib/python3.8/site-packages/werkzeug/exceptions.py", line 940, in abort
    _aborter(status, *args, **kwargs)
  File "/media/khalil-gazairly/aser/ITI/Flask/flask_todo/todo_env/lib/python3.8/site-packages/werkzeug/exceptions.py", line 923, in __call__
    raise self.mapping[code](*args, **kwargs)
werkzeug.exceptions.InternalServerError: 500 Internal Server Error: The server encountered an internal error and was unable to complete your request. Either the server is overloaded or there is an error in the application.
20-Nov-21 00:07:07 werkzeug - INFO - 127.0.0.1 - - [20/Nov/2021 00:07:07] "[35m[1mPOST /api/v1/todo HTTP/1.1[0m" 500 -
20-Nov-21 00:07:12 werkzeug - INFO - 127.0.0.1 - - [20/Nov/2021 00:07:12] "GET /api/v1/todo HTTP/1.1" 200 -
20-Nov-21 00:08:37 werkzeug - INFO -  * Detected change in '/media/khalil-gazairly/aser/ITI/Flask/flask_todo/todo/app.py', reloading
20-Nov-21 00:08:37 werkzeug - INFO -  * Restarting with stat
20-Nov-21 00:08:38 werkzeug - WARNING -  * Debugger is active!
20-Nov-21 00:08:38 werkzeug - INFO -  * Debugger PIN: 444-631-731
20-Nov-21 00:08:40 werkzeug - INFO - 127.0.0.1 - - [20/Nov/2021 00:08:40] "GET /api/v1/todo HTTP/1.1" 200 -
20-Nov-21 00:08:44 app - ERROR - Exception on /api/v1/todo [POST]
Traceback (most recent call last):
  File "/media/khalil-gazairly/aser/ITI/Flask/flask_todo/todo_env/lib/python3.8/site-packages/sqlalchemy/engine/base.py", line 1802, in _execute_context
    self.dialect.do_execute(
  File "/media/khalil-gazairly/aser/ITI/Flask/flask_todo/todo_env/lib/python3.8/site-packages/sqlalchemy/engine/default.py", line 719, in do_execute
    cursor.execute(statement, parameters)
sqlite3.IntegrityError: NOT NULL constraint failed: todo.name

The above exception was the direct cause of the following exception:

Traceback (most recent call last):
  File "/media/khalil-gazairly/aser/ITI/Flask/flask_todo/todo/app.py", line 52, in post
    db.session.commit()  # commit to db
  File "<string>", line 2, in commit
  File "/media/khalil-gazairly/aser/ITI/Flask/flask_todo/todo_env/lib/python3.8/site-packages/sqlalchemy/orm/session.py", line 1428, in commit
    self._transaction.commit(_to_root=self.future)
  File "/media/khalil-gazairly/aser/ITI/Flask/flask_todo/todo_env/lib/python3.8/site-packages/sqlalchemy/orm/session.py", line 829, in commit
    self._prepare_impl()
  File "/media/khalil-gazairly/aser/ITI/Flask/flask_todo/todo_env/lib/python3.8/site-packages/sqlalchemy/orm/session.py", line 808, in _prepare_impl
    self.session.flush()
  File "/media/khalil-gazairly/aser/ITI/Flask/flask_todo/todo_env/lib/python3.8/site-packages/sqlalchemy/orm/session.py", line 3345, in flush
    self._flush(objects)
  File "/media/khalil-gazairly/aser/ITI/Flask/flask_todo/todo_env/lib/python3.8/site-packages/sqlalchemy/orm/session.py", line 3485, in _flush
    transaction.rollback(_capture_exception=True)
  File "/media/khalil-gazairly/aser/ITI/Flask/flask_todo/todo_env/lib/python3.8/site-packages/sqlalchemy/util/langhelpers.py", line 70, in __exit__
    compat.raise_(
  File "/media/khalil-gazairly/aser/ITI/Flask/flask_todo/todo_env/lib/python3.8/site-packages/sqlalchemy/util/compat.py", line 207, in raise_
    raise exception
  File "/media/khalil-gazairly/aser/ITI/Flask/flask_todo/todo_env/lib/python3.8/site-packages/sqlalchemy/orm/session.py", line 3445, in _flush
    flush_context.execute()
  File "/media/khalil-gazairly/aser/ITI/Flask/flask_todo/todo_env/lib/python3.8/site-packages/sqlalchemy/orm/unitofwork.py", line 456, in execute
    rec.execute(self)
  File "/media/khalil-gazairly/aser/ITI/Flask/flask_todo/todo_env/lib/python3.8/site-packages/sqlalchemy/orm/unitofwork.py", line 630, in execute
    util.preloaded.orm_persistence.save_obj(
  File "/media/khalil-gazairly/aser/ITI/Flask/flask_todo/todo_env/lib/python3.8/site-packages/sqlalchemy/orm/persistence.py", line 244, in save_obj
    _emit_insert_statements(
  File "/media/khalil-gazairly/aser/ITI/Flask/flask_todo/todo_env/lib/python3.8/site-packages/sqlalchemy/orm/persistence.py", line 1221, in _emit_insert_statements
    result = connection._execute_20(
  File "/media/khalil-gazairly/aser/ITI/Flask/flask_todo/todo_env/lib/python3.8/site-packages/sqlalchemy/engine/base.py", line 1614, in _execute_20
    return meth(self, args_10style, kwargs_10style, execution_options)
  File "/media/khalil-gazairly/aser/ITI/Flask/flask_todo/todo_env/lib/python3.8/site-packages/sqlalchemy/sql/elements.py", line 325, in _execute_on_connection
    return connection._execute_clauseelement(
  File "/media/khalil-gazairly/aser/ITI/Flask/flask_todo/todo_env/lib/python3.8/site-packages/sqlalchemy/engine/base.py", line 1481, in _execute_clauseelement
    ret = self._execute_context(
  File "/media/khalil-gazairly/aser/ITI/Flask/flask_todo/todo_env/lib/python3.8/site-packages/sqlalchemy/engine/base.py", line 1845, in _execute_context
    self._handle_dbapi_exception(
  File "/media/khalil-gazairly/aser/ITI/Flask/flask_todo/todo_env/lib/python3.8/site-packages/sqlalchemy/engine/base.py", line 2026, in _handle_dbapi_exception
    util.raise_(
  File "/media/khalil-gazairly/aser/ITI/Flask/flask_todo/todo_env/lib/python3.8/site-packages/sqlalchemy/util/compat.py", line 207, in raise_
    raise exception
  File "/media/khalil-gazairly/aser/ITI/Flask/flask_todo/todo_env/lib/python3.8/site-packages/sqlalchemy/engine/base.py", line 1802, in _execute_context
    self.dialect.do_execute(
  File "/media/khalil-gazairly/aser/ITI/Flask/flask_todo/todo_env/lib/python3.8/site-packages/sqlalchemy/engine/default.py", line 719, in do_execute
    cursor.execute(statement, parameters)
sqlalchemy.exc.IntegrityError: (sqlite3.IntegrityError) NOT NULL constraint failed: todo.name
[SQL: INSERT INTO todo (name, priority, description, finished, created_at) VALUES (?, ?, ?, ?, ?)]
[parameters: (None, '10', 'task 4444', 0, '2021-11-20 00:08:44.733254')]
(Background on this error at: https://sqlalche.me/e/14/gkpj)

During handling of the above exception, another exception occurred:

Traceback (most recent call last):
  File "/media/khalil-gazairly/aser/ITI/Flask/flask_todo/todo_env/lib/python3.8/site-packages/flask/app.py", line 1516, in full_dispatch_request
    rv = self.dispatch_request()
  File "/media/khalil-gazairly/aser/ITI/Flask/flask_todo/todo_env/lib/python3.8/site-packages/flask/app.py", line 1502, in dispatch_request
    return self.ensure_sync(self.view_functions[rule.endpoint])(**req.view_args)
  File "/media/khalil-gazairly/aser/ITI/Flask/flask_todo/todo_env/lib/python3.8/site-packages/flask_restful/__init__.py", line 467, in wrapper
    resp = resource(*args, **kwargs)
  File "/media/khalil-gazairly/aser/ITI/Flask/flask_todo/todo_env/lib/python3.8/site-packages/flask/views.py", line 84, in view
    return current_app.ensure_sync(self.dispatch_request)(*args, **kwargs)
  File "/media/khalil-gazairly/aser/ITI/Flask/flask_todo/todo_env/lib/python3.8/site-packages/flask_restful/__init__.py", line 582, in dispatch_request
    resp = meth(*args, **kwargs)
  File "/media/khalil-gazairly/aser/ITI/Flask/flask_todo/todo/app.py", line 57, in post
    abort(500, message='Internal Server Error')
  File "/media/khalil-gazairly/aser/ITI/Flask/flask_todo/todo_env/lib/python3.8/site-packages/flask_restful/__init__.py", line 31, in abort
    original_flask_abort(http_status_code)
  File "/media/khalil-gazairly/aser/ITI/Flask/flask_todo/todo_env/lib/python3.8/site-packages/werkzeug/exceptions.py", line 940, in abort
    _aborter(status, *args, **kwargs)
  File "/media/khalil-gazairly/aser/ITI/Flask/flask_todo/todo_env/lib/python3.8/site-packages/werkzeug/exceptions.py", line 923, in __call__
    raise self.mapping[code](*args, **kwargs)
werkzeug.exceptions.InternalServerError: 500 Internal Server Error: The server encountered an internal error and was unable to complete your request. Either the server is overloaded or there is an error in the application.
20-Nov-21 00:08:44 werkzeug - INFO - 127.0.0.1 - - [20/Nov/2021 00:08:44] "[35m[1mPOST /api/v1/todo HTTP/1.1[0m" 500 -
20-Nov-21 00:09:02 app - ERROR - Exception on /api/v1/todo [POST]
Traceback (most recent call last):
  File "/media/khalil-gazairly/aser/ITI/Flask/flask_todo/todo_env/lib/python3.8/site-packages/sqlalchemy/engine/base.py", line 1802, in _execute_context
    self.dialect.do_execute(
  File "/media/khalil-gazairly/aser/ITI/Flask/flask_todo/todo_env/lib/python3.8/site-packages/sqlalchemy/engine/default.py", line 719, in do_execute
    cursor.execute(statement, parameters)
sqlite3.IntegrityError: NOT NULL constraint failed: todo.name

The above exception was the direct cause of the following exception:

Traceback (most recent call last):
  File "/media/khalil-gazairly/aser/ITI/Flask/flask_todo/todo/app.py", line 52, in post
    db.session.commit()  # commit to db
  File "<string>", line 2, in commit
  File "/media/khalil-gazairly/aser/ITI/Flask/flask_todo/todo_env/lib/python3.8/site-packages/sqlalchemy/orm/session.py", line 1428, in commit
    self._transaction.commit(_to_root=self.future)
  File "/media/khalil-gazairly/aser/ITI/Flask/flask_todo/todo_env/lib/python3.8/site-packages/sqlalchemy/orm/session.py", line 829, in commit
    self._prepare_impl()
  File "/media/khalil-gazairly/aser/ITI/Flask/flask_todo/todo_env/lib/python3.8/site-packages/sqlalchemy/orm/session.py", line 808, in _prepare_impl
    self.session.flush()
  File "/media/khalil-gazairly/aser/ITI/Flask/flask_todo/todo_env/lib/python3.8/site-packages/sqlalchemy/orm/session.py", line 3345, in flush
    self._flush(objects)
  File "/media/khalil-gazairly/aser/ITI/Flask/flask_todo/todo_env/lib/python3.8/site-packages/sqlalchemy/orm/session.py", line 3485, in _flush
    transaction.rollback(_capture_exception=True)
  File "/media/khalil-gazairly/aser/ITI/Flask/flask_todo/todo_env/lib/python3.8/site-packages/sqlalchemy/util/langhelpers.py", line 70, in __exit__
    compat.raise_(
  File "/media/khalil-gazairly/aser/ITI/Flask/flask_todo/todo_env/lib/python3.8/site-packages/sqlalchemy/util/compat.py", line 207, in raise_
    raise exception
  File "/media/khalil-gazairly/aser/ITI/Flask/flask_todo/todo_env/lib/python3.8/site-packages/sqlalchemy/orm/session.py", line 3445, in _flush
    flush_context.execute()
  File "/media/khalil-gazairly/aser/ITI/Flask/flask_todo/todo_env/lib/python3.8/site-packages/sqlalchemy/orm/unitofwork.py", line 456, in execute
    rec.execute(self)
  File "/media/khalil-gazairly/aser/ITI/Flask/flask_todo/todo_env/lib/python3.8/site-packages/sqlalchemy/orm/unitofwork.py", line 630, in execute
    util.preloaded.orm_persistence.save_obj(
  File "/media/khalil-gazairly/aser/ITI/Flask/flask_todo/todo_env/lib/python3.8/site-packages/sqlalchemy/orm/persistence.py", line 244, in save_obj
    _emit_insert_statements(
  File "/media/khalil-gazairly/aser/ITI/Flask/flask_todo/todo_env/lib/python3.8/site-packages/sqlalchemy/orm/persistence.py", line 1221, in _emit_insert_statements
    result = connection._execute_20(
  File "/media/khalil-gazairly/aser/ITI/Flask/flask_todo/todo_env/lib/python3.8/site-packages/sqlalchemy/engine/base.py", line 1614, in _execute_20
    return meth(self, args_10style, kwargs_10style, execution_options)
  File "/media/khalil-gazairly/aser/ITI/Flask/flask_todo/todo_env/lib/python3.8/site-packages/sqlalchemy/sql/elements.py", line 325, in _execute_on_connection
    return connection._execute_clauseelement(
  File "/media/khalil-gazairly/aser/ITI/Flask/flask_todo/todo_env/lib/python3.8/site-packages/sqlalchemy/engine/base.py", line 1481, in _execute_clauseelement
    ret = self._execute_context(
  File "/media/khalil-gazairly/aser/ITI/Flask/flask_todo/todo_env/lib/python3.8/site-packages/sqlalchemy/engine/base.py", line 1845, in _execute_context
    self._handle_dbapi_exception(
  File "/media/khalil-gazairly/aser/ITI/Flask/flask_todo/todo_env/lib/python3.8/site-packages/sqlalchemy/engine/base.py", line 2026, in _handle_dbapi_exception
    util.raise_(
  File "/media/khalil-gazairly/aser/ITI/Flask/flask_todo/todo_env/lib/python3.8/site-packages/sqlalchemy/util/compat.py", line 207, in raise_
    raise exception
  File "/media/khalil-gazairly/aser/ITI/Flask/flask_todo/todo_env/lib/python3.8/site-packages/sqlalchemy/engine/base.py", line 1802, in _execute_context
    self.dialect.do_execute(
  File "/media/khalil-gazairly/aser/ITI/Flask/flask_todo/todo_env/lib/python3.8/site-packages/sqlalchemy/engine/default.py", line 719, in do_execute
    cursor.execute(statement, parameters)
sqlalchemy.exc.IntegrityError: (sqlite3.IntegrityError) NOT NULL constraint failed: todo.name
[SQL: INSERT INTO todo (name, priority, description, finished, created_at) VALUES (?, ?, ?, ?, ?)]
[parameters: (None, '10', 'task 4444', 0, '2021-11-20 00:09:02.304211')]
(Background on this error at: https://sqlalche.me/e/14/gkpj)

During handling of the above exception, another exception occurred:

Traceback (most recent call last):
  File "/media/khalil-gazairly/aser/ITI/Flask/flask_todo/todo_env/lib/python3.8/site-packages/flask/app.py", line 1516, in full_dispatch_request
    rv = self.dispatch_request()
  File "/media/khalil-gazairly/aser/ITI/Flask/flask_todo/todo_env/lib/python3.8/site-packages/flask/app.py", line 1502, in dispatch_request
    return self.ensure_sync(self.view_functions[rule.endpoint])(**req.view_args)
  File "/media/khalil-gazairly/aser/ITI/Flask/flask_todo/todo_env/lib/python3.8/site-packages/flask_restful/__init__.py", line 467, in wrapper
    resp = resource(*args, **kwargs)
  File "/media/khalil-gazairly/aser/ITI/Flask/flask_todo/todo_env/lib/python3.8/site-packages/flask/views.py", line 84, in view
    return current_app.ensure_sync(self.dispatch_request)(*args, **kwargs)
  File "/media/khalil-gazairly/aser/ITI/Flask/flask_todo/todo_env/lib/python3.8/site-packages/flask_restful/__init__.py", line 582, in dispatch_request
    resp = meth(*args, **kwargs)
  File "/media/khalil-gazairly/aser/ITI/Flask/flask_todo/todo/app.py", line 57, in post
    abort(500, message='Internal Server Error')
  File "/media/khalil-gazairly/aser/ITI/Flask/flask_todo/todo_env/lib/python3.8/site-packages/flask_restful/__init__.py", line 31, in abort
    original_flask_abort(http_status_code)
  File "/media/khalil-gazairly/aser/ITI/Flask/flask_todo/todo_env/lib/python3.8/site-packages/werkzeug/exceptions.py", line 940, in abort
    _aborter(status, *args, **kwargs)
  File "/media/khalil-gazairly/aser/ITI/Flask/flask_todo/todo_env/lib/python3.8/site-packages/werkzeug/exceptions.py", line 923, in __call__
    raise self.mapping[code](*args, **kwargs)
werkzeug.exceptions.InternalServerError: 500 Internal Server Error: The server encountered an internal error and was unable to complete your request. Either the server is overloaded or there is an error in the application.
20-Nov-21 00:09:02 werkzeug - INFO - 127.0.0.1 - - [20/Nov/2021 00:09:02] "[35m[1mPOST /api/v1/todo HTTP/1.1[0m" 500 -
20-Nov-21 00:11:25 werkzeug - INFO -  * Detected change in '/media/khalil-gazairly/aser/ITI/Flask/flask_todo/todo/app.py', reloading
20-Nov-21 00:11:25 werkzeug - INFO -  * Restarting with stat
20-Nov-21 00:11:27 werkzeug - WARNING -  * Debugger is active!
20-Nov-21 00:11:27 werkzeug - INFO -  * Debugger PIN: 444-631-731
20-Nov-21 00:11:27 app - ERROR - Exception on /api/v1/todo [POST]
Traceback (most recent call last):
  File "/media/khalil-gazairly/aser/ITI/Flask/flask_todo/todo_env/lib/python3.8/site-packages/sqlalchemy/engine/base.py", line 1802, in _execute_context
    self.dialect.do_execute(
  File "/media/khalil-gazairly/aser/ITI/Flask/flask_todo/todo_env/lib/python3.8/site-packages/sqlalchemy/engine/default.py", line 719, in do_execute
    cursor.execute(statement, parameters)
sqlite3.IntegrityError: NOT NULL constraint failed: todo.name

The above exception was the direct cause of the following exception:

Traceback (most recent call last):
  File "/media/khalil-gazairly/aser/ITI/Flask/flask_todo/todo/app.py", line 52, in post
    db.session.commit()  # commit to db
  File "<string>", line 2, in commit
  File "/media/khalil-gazairly/aser/ITI/Flask/flask_todo/todo_env/lib/python3.8/site-packages/sqlalchemy/orm/session.py", line 1428, in commit
    self._transaction.commit(_to_root=self.future)
  File "/media/khalil-gazairly/aser/ITI/Flask/flask_todo/todo_env/lib/python3.8/site-packages/sqlalchemy/orm/session.py", line 829, in commit
    self._prepare_impl()
  File "/media/khalil-gazairly/aser/ITI/Flask/flask_todo/todo_env/lib/python3.8/site-packages/sqlalchemy/orm/session.py", line 808, in _prepare_impl
    self.session.flush()
  File "/media/khalil-gazairly/aser/ITI/Flask/flask_todo/todo_env/lib/python3.8/site-packages/sqlalchemy/orm/session.py", line 3345, in flush
    self._flush(objects)
  File "/media/khalil-gazairly/aser/ITI/Flask/flask_todo/todo_env/lib/python3.8/site-packages/sqlalchemy/orm/session.py", line 3485, in _flush
    transaction.rollback(_capture_exception=True)
  File "/media/khalil-gazairly/aser/ITI/Flask/flask_todo/todo_env/lib/python3.8/site-packages/sqlalchemy/util/langhelpers.py", line 70, in __exit__
    compat.raise_(
  File "/media/khalil-gazairly/aser/ITI/Flask/flask_todo/todo_env/lib/python3.8/site-packages/sqlalchemy/util/compat.py", line 207, in raise_
    raise exception
  File "/media/khalil-gazairly/aser/ITI/Flask/flask_todo/todo_env/lib/python3.8/site-packages/sqlalchemy/orm/session.py", line 3445, in _flush
    flush_context.execute()
  File "/media/khalil-gazairly/aser/ITI/Flask/flask_todo/todo_env/lib/python3.8/site-packages/sqlalchemy/orm/unitofwork.py", line 456, in execute
    rec.execute(self)
  File "/media/khalil-gazairly/aser/ITI/Flask/flask_todo/todo_env/lib/python3.8/site-packages/sqlalchemy/orm/unitofwork.py", line 630, in execute
    util.preloaded.orm_persistence.save_obj(
  File "/media/khalil-gazairly/aser/ITI/Flask/flask_todo/todo_env/lib/python3.8/site-packages/sqlalchemy/orm/persistence.py", line 244, in save_obj
    _emit_insert_statements(
  File "/media/khalil-gazairly/aser/ITI/Flask/flask_todo/todo_env/lib/python3.8/site-packages/sqlalchemy/orm/persistence.py", line 1221, in _emit_insert_statements
    result = connection._execute_20(
  File "/media/khalil-gazairly/aser/ITI/Flask/flask_todo/todo_env/lib/python3.8/site-packages/sqlalchemy/engine/base.py", line 1614, in _execute_20
    return meth(self, args_10style, kwargs_10style, execution_options)
  File "/media/khalil-gazairly/aser/ITI/Flask/flask_todo/todo_env/lib/python3.8/site-packages/sqlalchemy/sql/elements.py", line 325, in _execute_on_connection
    return connection._execute_clauseelement(
  File "/media/khalil-gazairly/aser/ITI/Flask/flask_todo/todo_env/lib/python3.8/site-packages/sqlalchemy/engine/base.py", line 1481, in _execute_clauseelement
    ret = self._execute_context(
  File "/media/khalil-gazairly/aser/ITI/Flask/flask_todo/todo_env/lib/python3.8/site-packages/sqlalchemy/engine/base.py", line 1845, in _execute_context
    self._handle_dbapi_exception(
  File "/media/khalil-gazairly/aser/ITI/Flask/flask_todo/todo_env/lib/python3.8/site-packages/sqlalchemy/engine/base.py", line 2026, in _handle_dbapi_exception
    util.raise_(
  File "/media/khalil-gazairly/aser/ITI/Flask/flask_todo/todo_env/lib/python3.8/site-packages/sqlalchemy/util/compat.py", line 207, in raise_
    raise exception
  File "/media/khalil-gazairly/aser/ITI/Flask/flask_todo/todo_env/lib/python3.8/site-packages/sqlalchemy/engine/base.py", line 1802, in _execute_context
    self.dialect.do_execute(
  File "/media/khalil-gazairly/aser/ITI/Flask/flask_todo/todo_env/lib/python3.8/site-packages/sqlalchemy/engine/default.py", line 719, in do_execute
    cursor.execute(statement, parameters)
sqlalchemy.exc.IntegrityError: (sqlite3.IntegrityError) NOT NULL constraint failed: todo.name
[SQL: INSERT INTO todo (name, priority, description, finished, created_at) VALUES (?, ?, ?, ?, ?)]
[parameters: (None, '10', 'task 4444', 0, '2021-11-20 00:11:27.876628')]
(Background on this error at: https://sqlalche.me/e/14/gkpj)

During handling of the above exception, another exception occurred:

Traceback (most recent call last):
  File "/media/khalil-gazairly/aser/ITI/Flask/flask_todo/todo_env/lib/python3.8/site-packages/flask/app.py", line 1516, in full_dispatch_request
    rv = self.dispatch_request()
  File "/media/khalil-gazairly/aser/ITI/Flask/flask_todo/todo_env/lib/python3.8/site-packages/flask/app.py", line 1502, in dispatch_request
    return self.ensure_sync(self.view_functions[rule.endpoint])(**req.view_args)
  File "/media/khalil-gazairly/aser/ITI/Flask/flask_todo/todo_env/lib/python3.8/site-packages/flask_restful/__init__.py", line 467, in wrapper
    resp = resource(*args, **kwargs)
  File "/media/khalil-gazairly/aser/ITI/Flask/flask_todo/todo_env/lib/python3.8/site-packages/flask/views.py", line 84, in view
    return current_app.ensure_sync(self.dispatch_request)(*args, **kwargs)
  File "/media/khalil-gazairly/aser/ITI/Flask/flask_todo/todo_env/lib/python3.8/site-packages/flask_restful/__init__.py", line 582, in dispatch_request
    resp = meth(*args, **kwargs)
  File "/media/khalil-gazairly/aser/ITI/Flask/flask_todo/todo/app.py", line 57, in post
    abort(500, message='Internal Server Error')
  File "/media/khalil-gazairly/aser/ITI/Flask/flask_todo/todo_env/lib/python3.8/site-packages/flask_restful/__init__.py", line 31, in abort
    original_flask_abort(http_status_code)
  File "/media/khalil-gazairly/aser/ITI/Flask/flask_todo/todo_env/lib/python3.8/site-packages/werkzeug/exceptions.py", line 940, in abort
    _aborter(status, *args, **kwargs)
  File "/media/khalil-gazairly/aser/ITI/Flask/flask_todo/todo_env/lib/python3.8/site-packages/werkzeug/exceptions.py", line 923, in __call__
    raise self.mapping[code](*args, **kwargs)
werkzeug.exceptions.InternalServerError: 500 Internal Server Error: The server encountered an internal error and was unable to complete your request. Either the server is overloaded or there is an error in the application.
20-Nov-21 00:11:28 werkzeug - INFO - 127.0.0.1 - - [20/Nov/2021 00:11:28] "[35m[1mPOST /api/v1/todo HTTP/1.1[0m" 500 -
20-Nov-21 00:11:50 app - ERROR - Exception on /api/v1/todo [POST]
Traceback (most recent call last):
  File "/media/khalil-gazairly/aser/ITI/Flask/flask_todo/todo_env/lib/python3.8/site-packages/sqlalchemy/engine/base.py", line 1802, in _execute_context
    self.dialect.do_execute(
  File "/media/khalil-gazairly/aser/ITI/Flask/flask_todo/todo_env/lib/python3.8/site-packages/sqlalchemy/engine/default.py", line 719, in do_execute
    cursor.execute(statement, parameters)
sqlite3.IntegrityError: NOT NULL constraint failed: todo.name

The above exception was the direct cause of the following exception:

Traceback (most recent call last):
  File "/media/khalil-gazairly/aser/ITI/Flask/flask_todo/todo/app.py", line 52, in post
    db.session.commit()  # commit to db
  File "<string>", line 2, in commit
  File "/media/khalil-gazairly/aser/ITI/Flask/flask_todo/todo_env/lib/python3.8/site-packages/sqlalchemy/orm/session.py", line 1428, in commit
    self._transaction.commit(_to_root=self.future)
  File "/media/khalil-gazairly/aser/ITI/Flask/flask_todo/todo_env/lib/python3.8/site-packages/sqlalchemy/orm/session.py", line 829, in commit
    self._prepare_impl()
  File "/media/khalil-gazairly/aser/ITI/Flask/flask_todo/todo_env/lib/python3.8/site-packages/sqlalchemy/orm/session.py", line 808, in _prepare_impl
    self.session.flush()
  File "/media/khalil-gazairly/aser/ITI/Flask/flask_todo/todo_env/lib/python3.8/site-packages/sqlalchemy/orm/session.py", line 3345, in flush
    self._flush(objects)
  File "/media/khalil-gazairly/aser/ITI/Flask/flask_todo/todo_env/lib/python3.8/site-packages/sqlalchemy/orm/session.py", line 3485, in _flush
    transaction.rollback(_capture_exception=True)
  File "/media/khalil-gazairly/aser/ITI/Flask/flask_todo/todo_env/lib/python3.8/site-packages/sqlalchemy/util/langhelpers.py", line 70, in __exit__
    compat.raise_(
  File "/media/khalil-gazairly/aser/ITI/Flask/flask_todo/todo_env/lib/python3.8/site-packages/sqlalchemy/util/compat.py", line 207, in raise_
    raise exception
  File "/media/khalil-gazairly/aser/ITI/Flask/flask_todo/todo_env/lib/python3.8/site-packages/sqlalchemy/orm/session.py", line 3445, in _flush
    flush_context.execute()
  File "/media/khalil-gazairly/aser/ITI/Flask/flask_todo/todo_env/lib/python3.8/site-packages/sqlalchemy/orm/unitofwork.py", line 456, in execute
    rec.execute(self)
  File "/media/khalil-gazairly/aser/ITI/Flask/flask_todo/todo_env/lib/python3.8/site-packages/sqlalchemy/orm/unitofwork.py", line 630, in execute
    util.preloaded.orm_persistence.save_obj(
  File "/media/khalil-gazairly/aser/ITI/Flask/flask_todo/todo_env/lib/python3.8/site-packages/sqlalchemy/orm/persistence.py", line 244, in save_obj
    _emit_insert_statements(
  File "/media/khalil-gazairly/aser/ITI/Flask/flask_todo/todo_env/lib/python3.8/site-packages/sqlalchemy/orm/persistence.py", line 1221, in _emit_insert_statements
    result = connection._execute_20(
  File "/media/khalil-gazairly/aser/ITI/Flask/flask_todo/todo_env/lib/python3.8/site-packages/sqlalchemy/engine/base.py", line 1614, in _execute_20
    return meth(self, args_10style, kwargs_10style, execution_options)
  File "/media/khalil-gazairly/aser/ITI/Flask/flask_todo/todo_env/lib/python3.8/site-packages/sqlalchemy/sql/elements.py", line 325, in _execute_on_connection
    return connection._execute_clauseelement(
  File "/media/khalil-gazairly/aser/ITI/Flask/flask_todo/todo_env/lib/python3.8/site-packages/sqlalchemy/engine/base.py", line 1481, in _execute_clauseelement
    ret = self._execute_context(
  File "/media/khalil-gazairly/aser/ITI/Flask/flask_todo/todo_env/lib/python3.8/site-packages/sqlalchemy/engine/base.py", line 1845, in _execute_context
    self._handle_dbapi_exception(
  File "/media/khalil-gazairly/aser/ITI/Flask/flask_todo/todo_env/lib/python3.8/site-packages/sqlalchemy/engine/base.py", line 2026, in _handle_dbapi_exception
    util.raise_(
  File "/media/khalil-gazairly/aser/ITI/Flask/flask_todo/todo_env/lib/python3.8/site-packages/sqlalchemy/util/compat.py", line 207, in raise_
    raise exception
  File "/media/khalil-gazairly/aser/ITI/Flask/flask_todo/todo_env/lib/python3.8/site-packages/sqlalchemy/engine/base.py", line 1802, in _execute_context
    self.dialect.do_execute(
  File "/media/khalil-gazairly/aser/ITI/Flask/flask_todo/todo_env/lib/python3.8/site-packages/sqlalchemy/engine/default.py", line 719, in do_execute
    cursor.execute(statement, parameters)
sqlalchemy.exc.IntegrityError: (sqlite3.IntegrityError) NOT NULL constraint failed: todo.name
[SQL: INSERT INTO todo (name, priority, description, finished, created_at) VALUES (?, ?, ?, ?, ?)]
[parameters: (None, '10', 'task 4444', 0, '2021-11-20 00:11:50.501739')]
(Background on this error at: https://sqlalche.me/e/14/gkpj)

During handling of the above exception, another exception occurred:

Traceback (most recent call last):
  File "/media/khalil-gazairly/aser/ITI/Flask/flask_todo/todo_env/lib/python3.8/site-packages/flask/app.py", line 1516, in full_dispatch_request
    rv = self.dispatch_request()
  File "/media/khalil-gazairly/aser/ITI/Flask/flask_todo/todo_env/lib/python3.8/site-packages/flask/app.py", line 1502, in dispatch_request
    return self.ensure_sync(self.view_functions[rule.endpoint])(**req.view_args)
  File "/media/khalil-gazairly/aser/ITI/Flask/flask_todo/todo_env/lib/python3.8/site-packages/flask_restful/__init__.py", line 467, in wrapper
    resp = resource(*args, **kwargs)
  File "/media/khalil-gazairly/aser/ITI/Flask/flask_todo/todo_env/lib/python3.8/site-packages/flask/views.py", line 84, in view
    return current_app.ensure_sync(self.dispatch_request)(*args, **kwargs)
  File "/media/khalil-gazairly/aser/ITI/Flask/flask_todo/todo_env/lib/python3.8/site-packages/flask_restful/__init__.py", line 582, in dispatch_request
    resp = meth(*args, **kwargs)
  File "/media/khalil-gazairly/aser/ITI/Flask/flask_todo/todo/app.py", line 57, in post
    abort(500, message='Internal Server Error')
  File "/media/khalil-gazairly/aser/ITI/Flask/flask_todo/todo_env/lib/python3.8/site-packages/flask_restful/__init__.py", line 31, in abort
    original_flask_abort(http_status_code)
  File "/media/khalil-gazairly/aser/ITI/Flask/flask_todo/todo_env/lib/python3.8/site-packages/werkzeug/exceptions.py", line 940, in abort
    _aborter(status, *args, **kwargs)
  File "/media/khalil-gazairly/aser/ITI/Flask/flask_todo/todo_env/lib/python3.8/site-packages/werkzeug/exceptions.py", line 923, in __call__
    raise self.mapping[code](*args, **kwargs)
werkzeug.exceptions.InternalServerError: 500 Internal Server Error: The server encountered an internal error and was unable to complete your request. Either the server is overloaded or there is an error in the application.
20-Nov-21 00:11:50 werkzeug - INFO - 127.0.0.1 - - [20/Nov/2021 00:11:50] "[35m[1mPOST /api/v1/todo HTTP/1.1[0m" 500 -
20-Nov-21 00:12:07 app - ERROR - Exception on /api/v1/todo [POST]
Traceback (most recent call last):
  File "/media/khalil-gazairly/aser/ITI/Flask/flask_todo/todo_env/lib/python3.8/site-packages/sqlalchemy/engine/base.py", line 1802, in _execute_context
    self.dialect.do_execute(
  File "/media/khalil-gazairly/aser/ITI/Flask/flask_todo/todo_env/lib/python3.8/site-packages/sqlalchemy/engine/default.py", line 719, in do_execute
    cursor.execute(statement, parameters)
sqlite3.IntegrityError: NOT NULL constraint failed: todo.name

The above exception was the direct cause of the following exception:

Traceback (most recent call last):
  File "/media/khalil-gazairly/aser/ITI/Flask/flask_todo/todo/app.py", line 52, in post
    db.session.commit()  # commit to db
  File "<string>", line 2, in commit
  File "/media/khalil-gazairly/aser/ITI/Flask/flask_todo/todo_env/lib/python3.8/site-packages/sqlalchemy/orm/session.py", line 1428, in commit
    self._transaction.commit(_to_root=self.future)
  File "/media/khalil-gazairly/aser/ITI/Flask/flask_todo/todo_env/lib/python3.8/site-packages/sqlalchemy/orm/session.py", line 829, in commit
    self._prepare_impl()
  File "/media/khalil-gazairly/aser/ITI/Flask/flask_todo/todo_env/lib/python3.8/site-packages/sqlalchemy/orm/session.py", line 808, in _prepare_impl
    self.session.flush()
  File "/media/khalil-gazairly/aser/ITI/Flask/flask_todo/todo_env/lib/python3.8/site-packages/sqlalchemy/orm/session.py", line 3345, in flush
    self._flush(objects)
  File "/media/khalil-gazairly/aser/ITI/Flask/flask_todo/todo_env/lib/python3.8/site-packages/sqlalchemy/orm/session.py", line 3485, in _flush
    transaction.rollback(_capture_exception=True)
  File "/media/khalil-gazairly/aser/ITI/Flask/flask_todo/todo_env/lib/python3.8/site-packages/sqlalchemy/util/langhelpers.py", line 70, in __exit__
    compat.raise_(
  File "/media/khalil-gazairly/aser/ITI/Flask/flask_todo/todo_env/lib/python3.8/site-packages/sqlalchemy/util/compat.py", line 207, in raise_
    raise exception
  File "/media/khalil-gazairly/aser/ITI/Flask/flask_todo/todo_env/lib/python3.8/site-packages/sqlalchemy/orm/session.py", line 3445, in _flush
    flush_context.execute()
  File "/media/khalil-gazairly/aser/ITI/Flask/flask_todo/todo_env/lib/python3.8/site-packages/sqlalchemy/orm/unitofwork.py", line 456, in execute
    rec.execute(self)
  File "/media/khalil-gazairly/aser/ITI/Flask/flask_todo/todo_env/lib/python3.8/site-packages/sqlalchemy/orm/unitofwork.py", line 630, in execute
    util.preloaded.orm_persistence.save_obj(
  File "/media/khalil-gazairly/aser/ITI/Flask/flask_todo/todo_env/lib/python3.8/site-packages/sqlalchemy/orm/persistence.py", line 244, in save_obj
    _emit_insert_statements(
  File "/media/khalil-gazairly/aser/ITI/Flask/flask_todo/todo_env/lib/python3.8/site-packages/sqlalchemy/orm/persistence.py", line 1221, in _emit_insert_statements
    result = connection._execute_20(
  File "/media/khalil-gazairly/aser/ITI/Flask/flask_todo/todo_env/lib/python3.8/site-packages/sqlalchemy/engine/base.py", line 1614, in _execute_20
    return meth(self, args_10style, kwargs_10style, execution_options)
  File "/media/khalil-gazairly/aser/ITI/Flask/flask_todo/todo_env/lib/python3.8/site-packages/sqlalchemy/sql/elements.py", line 325, in _execute_on_connection
    return connection._execute_clauseelement(
  File "/media/khalil-gazairly/aser/ITI/Flask/flask_todo/todo_env/lib/python3.8/site-packages/sqlalchemy/engine/base.py", line 1481, in _execute_clauseelement
    ret = self._execute_context(
  File "/media/khalil-gazairly/aser/ITI/Flask/flask_todo/todo_env/lib/python3.8/site-packages/sqlalchemy/engine/base.py", line 1845, in _execute_context
    self._handle_dbapi_exception(
  File "/media/khalil-gazairly/aser/ITI/Flask/flask_todo/todo_env/lib/python3.8/site-packages/sqlalchemy/engine/base.py", line 2026, in _handle_dbapi_exception
    util.raise_(
  File "/media/khalil-gazairly/aser/ITI/Flask/flask_todo/todo_env/lib/python3.8/site-packages/sqlalchemy/util/compat.py", line 207, in raise_
    raise exception
  File "/media/khalil-gazairly/aser/ITI/Flask/flask_todo/todo_env/lib/python3.8/site-packages/sqlalchemy/engine/base.py", line 1802, in _execute_context
    self.dialect.do_execute(
  File "/media/khalil-gazairly/aser/ITI/Flask/flask_todo/todo_env/lib/python3.8/site-packages/sqlalchemy/engine/default.py", line 719, in do_execute
    cursor.execute(statement, parameters)
sqlalchemy.exc.IntegrityError: (sqlite3.IntegrityError) NOT NULL constraint failed: todo.name
[SQL: INSERT INTO todo (name, priority, description, finished, created_at) VALUES (?, ?, ?, ?, ?)]
[parameters: (None, '10', 'task 4444', 0, '2021-11-20 00:12:07.124008')]
(Background on this error at: https://sqlalche.me/e/14/gkpj)

During handling of the above exception, another exception occurred:

Traceback (most recent call last):
  File "/media/khalil-gazairly/aser/ITI/Flask/flask_todo/todo_env/lib/python3.8/site-packages/flask/app.py", line 1516, in full_dispatch_request
    rv = self.dispatch_request()
  File "/media/khalil-gazairly/aser/ITI/Flask/flask_todo/todo_env/lib/python3.8/site-packages/flask/app.py", line 1502, in dispatch_request
    return self.ensure_sync(self.view_functions[rule.endpoint])(**req.view_args)
  File "/media/khalil-gazairly/aser/ITI/Flask/flask_todo/todo_env/lib/python3.8/site-packages/flask_restful/__init__.py", line 467, in wrapper
    resp = resource(*args, **kwargs)
  File "/media/khalil-gazairly/aser/ITI/Flask/flask_todo/todo_env/lib/python3.8/site-packages/flask/views.py", line 84, in view
    return current_app.ensure_sync(self.dispatch_request)(*args, **kwargs)
  File "/media/khalil-gazairly/aser/ITI/Flask/flask_todo/todo_env/lib/python3.8/site-packages/flask_restful/__init__.py", line 582, in dispatch_request
    resp = meth(*args, **kwargs)
  File "/media/khalil-gazairly/aser/ITI/Flask/flask_todo/todo/app.py", line 57, in post
    abort(500, message='Internal Server Error')
  File "/media/khalil-gazairly/aser/ITI/Flask/flask_todo/todo_env/lib/python3.8/site-packages/flask_restful/__init__.py", line 31, in abort
    original_flask_abort(http_status_code)
  File "/media/khalil-gazairly/aser/ITI/Flask/flask_todo/todo_env/lib/python3.8/site-packages/werkzeug/exceptions.py", line 940, in abort
    _aborter(status, *args, **kwargs)
  File "/media/khalil-gazairly/aser/ITI/Flask/flask_todo/todo_env/lib/python3.8/site-packages/werkzeug/exceptions.py", line 923, in __call__
    raise self.mapping[code](*args, **kwargs)
werkzeug.exceptions.InternalServerError: 500 Internal Server Error: The server encountered an internal error and was unable to complete your request. Either the server is overloaded or there is an error in the application.
20-Nov-21 00:12:07 werkzeug - INFO - 127.0.0.1 - - [20/Nov/2021 00:12:07] "[35m[1mPOST /api/v1/todo HTTP/1.1[0m" 500 -
20-Nov-21 00:14:33 werkzeug - INFO -  * Detected change in '/media/khalil-gazairly/aser/ITI/Flask/flask_todo/todo/app.py', reloading
20-Nov-21 00:14:33 werkzeug - INFO -  * Restarting with stat
20-Nov-21 00:14:36 werkzeug - WARNING -  * Debugger is active!
20-Nov-21 00:14:36 werkzeug - INFO -  * Debugger PIN: 444-631-731
20-Nov-21 00:14:36 app - ERROR - Exception on /api/v1/todo [POST]
Traceback (most recent call last):
  File "/media/khalil-gazairly/aser/ITI/Flask/flask_todo/todo_env/lib/python3.8/site-packages/sqlalchemy/engine/base.py", line 1802, in _execute_context
    self.dialect.do_execute(
  File "/media/khalil-gazairly/aser/ITI/Flask/flask_todo/todo_env/lib/python3.8/site-packages/sqlalchemy/engine/default.py", line 719, in do_execute
    cursor.execute(statement, parameters)
sqlite3.IntegrityError: NOT NULL constraint failed: todo.name

The above exception was the direct cause of the following exception:

Traceback (most recent call last):
  File "/media/khalil-gazairly/aser/ITI/Flask/flask_todo/todo/app.py", line 52, in post
    db.session.commit()
  File "<string>", line 2, in commit
  File "/media/khalil-gazairly/aser/ITI/Flask/flask_todo/todo_env/lib/python3.8/site-packages/sqlalchemy/orm/session.py", line 1428, in commit
    self._transaction.commit(_to_root=self.future)
  File "/media/khalil-gazairly/aser/ITI/Flask/flask_todo/todo_env/lib/python3.8/site-packages/sqlalchemy/orm/session.py", line 829, in commit
    self._prepare_impl()
  File "/media/khalil-gazairly/aser/ITI/Flask/flask_todo/todo_env/lib/python3.8/site-packages/sqlalchemy/orm/session.py", line 808, in _prepare_impl
    self.session.flush()
  File "/media/khalil-gazairly/aser/ITI/Flask/flask_todo/todo_env/lib/python3.8/site-packages/sqlalchemy/orm/session.py", line 3345, in flush
    self._flush(objects)
  File "/media/khalil-gazairly/aser/ITI/Flask/flask_todo/todo_env/lib/python3.8/site-packages/sqlalchemy/orm/session.py", line 3485, in _flush
    transaction.rollback(_capture_exception=True)
  File "/media/khalil-gazairly/aser/ITI/Flask/flask_todo/todo_env/lib/python3.8/site-packages/sqlalchemy/util/langhelpers.py", line 70, in __exit__
    compat.raise_(
  File "/media/khalil-gazairly/aser/ITI/Flask/flask_todo/todo_env/lib/python3.8/site-packages/sqlalchemy/util/compat.py", line 207, in raise_
    raise exception
  File "/media/khalil-gazairly/aser/ITI/Flask/flask_todo/todo_env/lib/python3.8/site-packages/sqlalchemy/orm/session.py", line 3445, in _flush
    flush_context.execute()
  File "/media/khalil-gazairly/aser/ITI/Flask/flask_todo/todo_env/lib/python3.8/site-packages/sqlalchemy/orm/unitofwork.py", line 456, in execute
    rec.execute(self)
  File "/media/khalil-gazairly/aser/ITI/Flask/flask_todo/todo_env/lib/python3.8/site-packages/sqlalchemy/orm/unitofwork.py", line 630, in execute
    util.preloaded.orm_persistence.save_obj(
  File "/media/khalil-gazairly/aser/ITI/Flask/flask_todo/todo_env/lib/python3.8/site-packages/sqlalchemy/orm/persistence.py", line 244, in save_obj
    _emit_insert_statements(
  File "/media/khalil-gazairly/aser/ITI/Flask/flask_todo/todo_env/lib/python3.8/site-packages/sqlalchemy/orm/persistence.py", line 1221, in _emit_insert_statements
    result = connection._execute_20(
  File "/media/khalil-gazairly/aser/ITI/Flask/flask_todo/todo_env/lib/python3.8/site-packages/sqlalchemy/engine/base.py", line 1614, in _execute_20
    return meth(self, args_10style, kwargs_10style, execution_options)
  File "/media/khalil-gazairly/aser/ITI/Flask/flask_todo/todo_env/lib/python3.8/site-packages/sqlalchemy/sql/elements.py", line 325, in _execute_on_connection
    return connection._execute_clauseelement(
  File "/media/khalil-gazairly/aser/ITI/Flask/flask_todo/todo_env/lib/python3.8/site-packages/sqlalchemy/engine/base.py", line 1481, in _execute_clauseelement
    ret = self._execute_context(
  File "/media/khalil-gazairly/aser/ITI/Flask/flask_todo/todo_env/lib/python3.8/site-packages/sqlalchemy/engine/base.py", line 1845, in _execute_context
    self._handle_dbapi_exception(
  File "/media/khalil-gazairly/aser/ITI/Flask/flask_todo/todo_env/lib/python3.8/site-packages/sqlalchemy/engine/base.py", line 2026, in _handle_dbapi_exception
    util.raise_(
  File "/media/khalil-gazairly/aser/ITI/Flask/flask_todo/todo_env/lib/python3.8/site-packages/sqlalchemy/util/compat.py", line 207, in raise_
    raise exception
  File "/media/khalil-gazairly/aser/ITI/Flask/flask_todo/todo_env/lib/python3.8/site-packages/sqlalchemy/engine/base.py", line 1802, in _execute_context
    self.dialect.do_execute(
  File "/media/khalil-gazairly/aser/ITI/Flask/flask_todo/todo_env/lib/python3.8/site-packages/sqlalchemy/engine/default.py", line 719, in do_execute
    cursor.execute(statement, parameters)
sqlalchemy.exc.IntegrityError: (sqlite3.IntegrityError) NOT NULL constraint failed: todo.name
[SQL: INSERT INTO todo (name, priority, description, finished, created_at) VALUES (?, ?, ?, ?, ?)]
[parameters: (None, '10', 'task 4444', 0, '2021-11-20 00:14:36.934669')]
(Background on this error at: https://sqlalche.me/e/14/gkpj)

During handling of the above exception, another exception occurred:

Traceback (most recent call last):
  File "/media/khalil-gazairly/aser/ITI/Flask/flask_todo/todo_env/lib/python3.8/site-packages/flask/app.py", line 1516, in full_dispatch_request
    rv = self.dispatch_request()
  File "/media/khalil-gazairly/aser/ITI/Flask/flask_todo/todo_env/lib/python3.8/site-packages/flask/app.py", line 1502, in dispatch_request
    return self.ensure_sync(self.view_functions[rule.endpoint])(**req.view_args)
  File "/media/khalil-gazairly/aser/ITI/Flask/flask_todo/todo_env/lib/python3.8/site-packages/flask_restful/__init__.py", line 467, in wrapper
    resp = resource(*args, **kwargs)
  File "/media/khalil-gazairly/aser/ITI/Flask/flask_todo/todo_env/lib/python3.8/site-packages/flask/views.py", line 84, in view
    return current_app.ensure_sync(self.dispatch_request)(*args, **kwargs)
  File "/media/khalil-gazairly/aser/ITI/Flask/flask_todo/todo_env/lib/python3.8/site-packages/flask_restful/__init__.py", line 582, in dispatch_request
    resp = meth(*args, **kwargs)
  File "/media/khalil-gazairly/aser/ITI/Flask/flask_todo/todo/app.py", line 57, in post
    abort(500, message='Internal Server Error')
  File "/media/khalil-gazairly/aser/ITI/Flask/flask_todo/todo_env/lib/python3.8/site-packages/flask_restful/__init__.py", line 31, in abort
    original_flask_abort(http_status_code)
  File "/media/khalil-gazairly/aser/ITI/Flask/flask_todo/todo_env/lib/python3.8/site-packages/werkzeug/exceptions.py", line 940, in abort
    _aborter(status, *args, **kwargs)
  File "/media/khalil-gazairly/aser/ITI/Flask/flask_todo/todo_env/lib/python3.8/site-packages/werkzeug/exceptions.py", line 923, in __call__
    raise self.mapping[code](*args, **kwargs)
werkzeug.exceptions.InternalServerError: 500 Internal Server Error: The server encountered an internal error and was unable to complete your request. Either the server is overloaded or there is an error in the application.
20-Nov-21 00:14:37 werkzeug - INFO - 127.0.0.1 - - [20/Nov/2021 00:14:37] "[35m[1mPOST /api/v1/todo HTTP/1.1[0m" 500 -
20-Nov-21 00:17:10 werkzeug - INFO -  * Detected change in '/media/khalil-gazairly/aser/ITI/Flask/flask_todo/todo/app.py', reloading
20-Nov-21 00:17:10 werkzeug - INFO -  * Restarting with stat
20-Nov-21 00:17:12 werkzeug - WARNING -  * Debugger is active!
20-Nov-21 00:17:12 werkzeug - INFO -  * Debugger PIN: 444-631-731
20-Nov-21 00:17:32 werkzeug - INFO -  * Detected change in '/media/khalil-gazairly/aser/ITI/Flask/flask_todo/todo/app.py', reloading
20-Nov-21 00:17:32 werkzeug - INFO -  * Restarting with stat
20-Nov-21 00:17:33 werkzeug - WARNING -  * Debugger is active!
20-Nov-21 00:17:33 werkzeug - INFO -  * Debugger PIN: 444-631-731
20-Nov-21 00:19:45 werkzeug - INFO -  * Running on http://127.0.0.1:5000/ (Press CTRL+C to quit)
20-Nov-21 00:19:45 werkzeug - INFO -  * Restarting with stat
20-Nov-21 00:19:46 werkzeug - WARNING -  * Debugger is active!
20-Nov-21 00:19:46 werkzeug - INFO -  * Debugger PIN: 444-631-731
20-Nov-21 00:19:52 app - ERROR - Exception on /api/v1/todo [POST]
Traceback (most recent call last):
  File "/media/khalil-gazairly/aser/ITI/Flask/flask_todo/todo_env/lib/python3.8/site-packages/sqlalchemy/engine/base.py", line 1802, in _execute_context
    self.dialect.do_execute(
  File "/media/khalil-gazairly/aser/ITI/Flask/flask_todo/todo_env/lib/python3.8/site-packages/sqlalchemy/engine/default.py", line 719, in do_execute
    cursor.execute(statement, parameters)
sqlite3.IntegrityError: NOT NULL constraint failed: todo.name

The above exception was the direct cause of the following exception:

Traceback (most recent call last):
  File "/media/khalil-gazairly/aser/ITI/Flask/flask_todo/todo/app.py", line 74, in post
    db.session.commit()
  File "<string>", line 2, in commit
  File "/media/khalil-gazairly/aser/ITI/Flask/flask_todo/todo_env/lib/python3.8/site-packages/sqlalchemy/orm/session.py", line 1428, in commit
    self._transaction.commit(_to_root=self.future)
  File "/media/khalil-gazairly/aser/ITI/Flask/flask_todo/todo_env/lib/python3.8/site-packages/sqlalchemy/orm/session.py", line 829, in commit
    self._prepare_impl()
  File "/media/khalil-gazairly/aser/ITI/Flask/flask_todo/todo_env/lib/python3.8/site-packages/sqlalchemy/orm/session.py", line 808, in _prepare_impl
    self.session.flush()
  File "/media/khalil-gazairly/aser/ITI/Flask/flask_todo/todo_env/lib/python3.8/site-packages/sqlalchemy/orm/session.py", line 3345, in flush
    self._flush(objects)
  File "/media/khalil-gazairly/aser/ITI/Flask/flask_todo/todo_env/lib/python3.8/site-packages/sqlalchemy/orm/session.py", line 3485, in _flush
    transaction.rollback(_capture_exception=True)
  File "/media/khalil-gazairly/aser/ITI/Flask/flask_todo/todo_env/lib/python3.8/site-packages/sqlalchemy/util/langhelpers.py", line 70, in __exit__
    compat.raise_(
  File "/media/khalil-gazairly/aser/ITI/Flask/flask_todo/todo_env/lib/python3.8/site-packages/sqlalchemy/util/compat.py", line 207, in raise_
    raise exception
  File "/media/khalil-gazairly/aser/ITI/Flask/flask_todo/todo_env/lib/python3.8/site-packages/sqlalchemy/orm/session.py", line 3445, in _flush
    flush_context.execute()
  File "/media/khalil-gazairly/aser/ITI/Flask/flask_todo/todo_env/lib/python3.8/site-packages/sqlalchemy/orm/unitofwork.py", line 456, in execute
    rec.execute(self)
  File "/media/khalil-gazairly/aser/ITI/Flask/flask_todo/todo_env/lib/python3.8/site-packages/sqlalchemy/orm/unitofwork.py", line 630, in execute
    util.preloaded.orm_persistence.save_obj(
  File "/media/khalil-gazairly/aser/ITI/Flask/flask_todo/todo_env/lib/python3.8/site-packages/sqlalchemy/orm/persistence.py", line 244, in save_obj
    _emit_insert_statements(
  File "/media/khalil-gazairly/aser/ITI/Flask/flask_todo/todo_env/lib/python3.8/site-packages/sqlalchemy/orm/persistence.py", line 1221, in _emit_insert_statements
    result = connection._execute_20(
  File "/media/khalil-gazairly/aser/ITI/Flask/flask_todo/todo_env/lib/python3.8/site-packages/sqlalchemy/engine/base.py", line 1614, in _execute_20
    return meth(self, args_10style, kwargs_10style, execution_options)
  File "/media/khalil-gazairly/aser/ITI/Flask/flask_todo/todo_env/lib/python3.8/site-packages/sqlalchemy/sql/elements.py", line 325, in _execute_on_connection
    return connection._execute_clauseelement(
  File "/media/khalil-gazairly/aser/ITI/Flask/flask_todo/todo_env/lib/python3.8/site-packages/sqlalchemy/engine/base.py", line 1481, in _execute_clauseelement
    ret = self._execute_context(
  File "/media/khalil-gazairly/aser/ITI/Flask/flask_todo/todo_env/lib/python3.8/site-packages/sqlalchemy/engine/base.py", line 1845, in _execute_context
    self._handle_dbapi_exception(
  File "/media/khalil-gazairly/aser/ITI/Flask/flask_todo/todo_env/lib/python3.8/site-packages/sqlalchemy/engine/base.py", line 2026, in _handle_dbapi_exception
    util.raise_(
  File "/media/khalil-gazairly/aser/ITI/Flask/flask_todo/todo_env/lib/python3.8/site-packages/sqlalchemy/util/compat.py", line 207, in raise_
    raise exception
  File "/media/khalil-gazairly/aser/ITI/Flask/flask_todo/todo_env/lib/python3.8/site-packages/sqlalchemy/engine/base.py", line 1802, in _execute_context
    self.dialect.do_execute(
  File "/media/khalil-gazairly/aser/ITI/Flask/flask_todo/todo_env/lib/python3.8/site-packages/sqlalchemy/engine/default.py", line 719, in do_execute
    cursor.execute(statement, parameters)
sqlalchemy.exc.IntegrityError: (sqlite3.IntegrityError) NOT NULL constraint failed: todo.name
[SQL: INSERT INTO todo (name, priority, description, finished, created_at) VALUES (?, ?, ?, ?, ?)]
[parameters: (None, '10', 'task 4444', 0, '2021-11-20 00:19:52.909722')]
(Background on this error at: https://sqlalche.me/e/14/gkpj)

During handling of the above exception, another exception occurred:

Traceback (most recent call last):
  File "/media/khalil-gazairly/aser/ITI/Flask/flask_todo/todo_env/lib/python3.8/site-packages/flask/app.py", line 1516, in full_dispatch_request
    rv = self.dispatch_request()
  File "/media/khalil-gazairly/aser/ITI/Flask/flask_todo/todo_env/lib/python3.8/site-packages/flask/app.py", line 1502, in dispatch_request
    return self.ensure_sync(self.view_functions[rule.endpoint])(**req.view_args)
  File "/media/khalil-gazairly/aser/ITI/Flask/flask_todo/todo_env/lib/python3.8/site-packages/flask_restful/__init__.py", line 467, in wrapper
    resp = resource(*args, **kwargs)
  File "/media/khalil-gazairly/aser/ITI/Flask/flask_todo/todo_env/lib/python3.8/site-packages/flask/views.py", line 84, in view
    return current_app.ensure_sync(self.dispatch_request)(*args, **kwargs)
  File "/media/khalil-gazairly/aser/ITI/Flask/flask_todo/todo_env/lib/python3.8/site-packages/flask_restful/__init__.py", line 582, in dispatch_request
    resp = meth(*args, **kwargs)
  File "/media/khalil-gazairly/aser/ITI/Flask/flask_todo/todo/app.py", line 79, in post
    abort(500, message='Internal Server Error')
  File "/media/khalil-gazairly/aser/ITI/Flask/flask_todo/todo_env/lib/python3.8/site-packages/flask_restful/__init__.py", line 31, in abort
    original_flask_abort(http_status_code)
  File "/media/khalil-gazairly/aser/ITI/Flask/flask_todo/todo_env/lib/python3.8/site-packages/werkzeug/exceptions.py", line 940, in abort
    _aborter(status, *args, **kwargs)
  File "/media/khalil-gazairly/aser/ITI/Flask/flask_todo/todo_env/lib/python3.8/site-packages/werkzeug/exceptions.py", line 923, in __call__
    raise self.mapping[code](*args, **kwargs)
werkzeug.exceptions.InternalServerError: 500 Internal Server Error: The server encountered an internal error and was unable to complete your request. Either the server is overloaded or there is an error in the application.
20-Nov-21 00:19:53 werkzeug - INFO - 127.0.0.1 - - [20/Nov/2021 00:19:53] "[35m[1mPOST /api/v1/todo HTTP/1.1[0m" 500 -
20-Nov-21 00:22:23 werkzeug - INFO -  * Detected change in '/media/khalil-gazairly/aser/ITI/Flask/flask_todo/todo/app.py', reloading
20-Nov-21 00:22:23 werkzeug - INFO -  * Restarting with stat
20-Nov-21 00:22:26 werkzeug - WARNING -  * Debugger is active!
20-Nov-21 00:22:26 werkzeug - INFO -  * Debugger PIN: 444-631-731
20-Nov-21 00:22:26 app - ERROR - Exception on /api/v1/todo [POST]
Traceback (most recent call last):
  File "/media/khalil-gazairly/aser/ITI/Flask/flask_todo/todo_env/lib/python3.8/site-packages/sqlalchemy/engine/base.py", line 1802, in _execute_context
    self.dialect.do_execute(
  File "/media/khalil-gazairly/aser/ITI/Flask/flask_todo/todo_env/lib/python3.8/site-packages/sqlalchemy/engine/default.py", line 719, in do_execute
    cursor.execute(statement, parameters)
sqlite3.IntegrityError: NOT NULL constraint failed: todo.name

The above exception was the direct cause of the following exception:

Traceback (most recent call last):
  File "/media/khalil-gazairly/aser/ITI/Flask/flask_todo/todo/app.py", line 74, in post
    db.session.commit()
  File "<string>", line 2, in commit
  File "/media/khalil-gazairly/aser/ITI/Flask/flask_todo/todo_env/lib/python3.8/site-packages/sqlalchemy/orm/session.py", line 1428, in commit
    self._transaction.commit(_to_root=self.future)
  File "/media/khalil-gazairly/aser/ITI/Flask/flask_todo/todo_env/lib/python3.8/site-packages/sqlalchemy/orm/session.py", line 829, in commit
    self._prepare_impl()
  File "/media/khalil-gazairly/aser/ITI/Flask/flask_todo/todo_env/lib/python3.8/site-packages/sqlalchemy/orm/session.py", line 808, in _prepare_impl
    self.session.flush()
  File "/media/khalil-gazairly/aser/ITI/Flask/flask_todo/todo_env/lib/python3.8/site-packages/sqlalchemy/orm/session.py", line 3345, in flush
    self._flush(objects)
  File "/media/khalil-gazairly/aser/ITI/Flask/flask_todo/todo_env/lib/python3.8/site-packages/sqlalchemy/orm/session.py", line 3485, in _flush
    transaction.rollback(_capture_exception=True)
  File "/media/khalil-gazairly/aser/ITI/Flask/flask_todo/todo_env/lib/python3.8/site-packages/sqlalchemy/util/langhelpers.py", line 70, in __exit__
    compat.raise_(
  File "/media/khalil-gazairly/aser/ITI/Flask/flask_todo/todo_env/lib/python3.8/site-packages/sqlalchemy/util/compat.py", line 207, in raise_
    raise exception
  File "/media/khalil-gazairly/aser/ITI/Flask/flask_todo/todo_env/lib/python3.8/site-packages/sqlalchemy/orm/session.py", line 3445, in _flush
    flush_context.execute()
  File "/media/khalil-gazairly/aser/ITI/Flask/flask_todo/todo_env/lib/python3.8/site-packages/sqlalchemy/orm/unitofwork.py", line 456, in execute
    rec.execute(self)
  File "/media/khalil-gazairly/aser/ITI/Flask/flask_todo/todo_env/lib/python3.8/site-packages/sqlalchemy/orm/unitofwork.py", line 630, in execute
    util.preloaded.orm_persistence.save_obj(
  File "/media/khalil-gazairly/aser/ITI/Flask/flask_todo/todo_env/lib/python3.8/site-packages/sqlalchemy/orm/persistence.py", line 244, in save_obj
    _emit_insert_statements(
  File "/media/khalil-gazairly/aser/ITI/Flask/flask_todo/todo_env/lib/python3.8/site-packages/sqlalchemy/orm/persistence.py", line 1221, in _emit_insert_statements
    result = connection._execute_20(
  File "/media/khalil-gazairly/aser/ITI/Flask/flask_todo/todo_env/lib/python3.8/site-packages/sqlalchemy/engine/base.py", line 1614, in _execute_20
    return meth(self, args_10style, kwargs_10style, execution_options)
  File "/media/khalil-gazairly/aser/ITI/Flask/flask_todo/todo_env/lib/python3.8/site-packages/sqlalchemy/sql/elements.py", line 325, in _execute_on_connection
    return connection._execute_clauseelement(
  File "/media/khalil-gazairly/aser/ITI/Flask/flask_todo/todo_env/lib/python3.8/site-packages/sqlalchemy/engine/base.py", line 1481, in _execute_clauseelement
    ret = self._execute_context(
  File "/media/khalil-gazairly/aser/ITI/Flask/flask_todo/todo_env/lib/python3.8/site-packages/sqlalchemy/engine/base.py", line 1845, in _execute_context
    self._handle_dbapi_exception(
  File "/media/khalil-gazairly/aser/ITI/Flask/flask_todo/todo_env/lib/python3.8/site-packages/sqlalchemy/engine/base.py", line 2026, in _handle_dbapi_exception
    util.raise_(
  File "/media/khalil-gazairly/aser/ITI/Flask/flask_todo/todo_env/lib/python3.8/site-packages/sqlalchemy/util/compat.py", line 207, in raise_
    raise exception
  File "/media/khalil-gazairly/aser/ITI/Flask/flask_todo/todo_env/lib/python3.8/site-packages/sqlalchemy/engine/base.py", line 1802, in _execute_context
    self.dialect.do_execute(
  File "/media/khalil-gazairly/aser/ITI/Flask/flask_todo/todo_env/lib/python3.8/site-packages/sqlalchemy/engine/default.py", line 719, in do_execute
    cursor.execute(statement, parameters)
sqlalchemy.exc.IntegrityError: (sqlite3.IntegrityError) NOT NULL constraint failed: todo.name
[SQL: INSERT INTO todo (name, priority, description, finished, created_at) VALUES (?, ?, ?, ?, ?)]
[parameters: (None, '10', 'task 4444', 0, '2021-11-20 00:22:26.335414')]
(Background on this error at: https://sqlalche.me/e/14/gkpj)

During handling of the above exception, another exception occurred:

Traceback (most recent call last):
  File "/media/khalil-gazairly/aser/ITI/Flask/flask_todo/todo_env/lib/python3.8/site-packages/flask/app.py", line 1516, in full_dispatch_request
    rv = self.dispatch_request()
  File "/media/khalil-gazairly/aser/ITI/Flask/flask_todo/todo_env/lib/python3.8/site-packages/flask/app.py", line 1502, in dispatch_request
    return self.ensure_sync(self.view_functions[rule.endpoint])(**req.view_args)
  File "/media/khalil-gazairly/aser/ITI/Flask/flask_todo/todo_env/lib/python3.8/site-packages/flask_restful/__init__.py", line 467, in wrapper
    resp = resource(*args, **kwargs)
  File "/media/khalil-gazairly/aser/ITI/Flask/flask_todo/todo_env/lib/python3.8/site-packages/flask/views.py", line 84, in view
    return current_app.ensure_sync(self.dispatch_request)(*args, **kwargs)
  File "/media/khalil-gazairly/aser/ITI/Flask/flask_todo/todo_env/lib/python3.8/site-packages/flask_restful/__init__.py", line 582, in dispatch_request
    resp = meth(*args, **kwargs)
  File "/media/khalil-gazairly/aser/ITI/Flask/flask_todo/todo/app.py", line 79, in post
    abort(500, message='Internal Server Error')
  File "/media/khalil-gazairly/aser/ITI/Flask/flask_todo/todo_env/lib/python3.8/site-packages/flask_restful/__init__.py", line 31, in abort
    original_flask_abort(http_status_code)
  File "/media/khalil-gazairly/aser/ITI/Flask/flask_todo/todo_env/lib/python3.8/site-packages/werkzeug/exceptions.py", line 940, in abort
    _aborter(status, *args, **kwargs)
  File "/media/khalil-gazairly/aser/ITI/Flask/flask_todo/todo_env/lib/python3.8/site-packages/werkzeug/exceptions.py", line 923, in __call__
    raise self.mapping[code](*args, **kwargs)
werkzeug.exceptions.InternalServerError: 500 Internal Server Error: The server encountered an internal error and was unable to complete your request. Either the server is overloaded or there is an error in the application.
20-Nov-21 00:22:26 werkzeug - INFO - 127.0.0.1 - - [20/Nov/2021 00:22:26] "[35m[1mPOST /api/v1/todo HTTP/1.1[0m" 500 -
20-Nov-21 00:22:43 app - ERROR - Exception on /api/v1/todo [POST]
Traceback (most recent call last):
  File "/media/khalil-gazairly/aser/ITI/Flask/flask_todo/todo_env/lib/python3.8/site-packages/sqlalchemy/engine/base.py", line 1802, in _execute_context
    self.dialect.do_execute(
  File "/media/khalil-gazairly/aser/ITI/Flask/flask_todo/todo_env/lib/python3.8/site-packages/sqlalchemy/engine/default.py", line 719, in do_execute
    cursor.execute(statement, parameters)
sqlite3.IntegrityError: NOT NULL constraint failed: todo.name

The above exception was the direct cause of the following exception:

Traceback (most recent call last):
  File "/media/khalil-gazairly/aser/ITI/Flask/flask_todo/todo/app.py", line 74, in post
    db.session.commit()
  File "<string>", line 2, in commit
  File "/media/khalil-gazairly/aser/ITI/Flask/flask_todo/todo_env/lib/python3.8/site-packages/sqlalchemy/orm/session.py", line 1428, in commit
    self._transaction.commit(_to_root=self.future)
  File "/media/khalil-gazairly/aser/ITI/Flask/flask_todo/todo_env/lib/python3.8/site-packages/sqlalchemy/orm/session.py", line 829, in commit
    self._prepare_impl()
  File "/media/khalil-gazairly/aser/ITI/Flask/flask_todo/todo_env/lib/python3.8/site-packages/sqlalchemy/orm/session.py", line 808, in _prepare_impl
    self.session.flush()
  File "/media/khalil-gazairly/aser/ITI/Flask/flask_todo/todo_env/lib/python3.8/site-packages/sqlalchemy/orm/session.py", line 3345, in flush
    self._flush(objects)
  File "/media/khalil-gazairly/aser/ITI/Flask/flask_todo/todo_env/lib/python3.8/site-packages/sqlalchemy/orm/session.py", line 3485, in _flush
    transaction.rollback(_capture_exception=True)
  File "/media/khalil-gazairly/aser/ITI/Flask/flask_todo/todo_env/lib/python3.8/site-packages/sqlalchemy/util/langhelpers.py", line 70, in __exit__
    compat.raise_(
  File "/media/khalil-gazairly/aser/ITI/Flask/flask_todo/todo_env/lib/python3.8/site-packages/sqlalchemy/util/compat.py", line 207, in raise_
    raise exception
  File "/media/khalil-gazairly/aser/ITI/Flask/flask_todo/todo_env/lib/python3.8/site-packages/sqlalchemy/orm/session.py", line 3445, in _flush
    flush_context.execute()
  File "/media/khalil-gazairly/aser/ITI/Flask/flask_todo/todo_env/lib/python3.8/site-packages/sqlalchemy/orm/unitofwork.py", line 456, in execute
    rec.execute(self)
  File "/media/khalil-gazairly/aser/ITI/Flask/flask_todo/todo_env/lib/python3.8/site-packages/sqlalchemy/orm/unitofwork.py", line 630, in execute
    util.preloaded.orm_persistence.save_obj(
  File "/media/khalil-gazairly/aser/ITI/Flask/flask_todo/todo_env/lib/python3.8/site-packages/sqlalchemy/orm/persistence.py", line 244, in save_obj
    _emit_insert_statements(
  File "/media/khalil-gazairly/aser/ITI/Flask/flask_todo/todo_env/lib/python3.8/site-packages/sqlalchemy/orm/persistence.py", line 1221, in _emit_insert_statements
    result = connection._execute_20(
  File "/media/khalil-gazairly/aser/ITI/Flask/flask_todo/todo_env/lib/python3.8/site-packages/sqlalchemy/engine/base.py", line 1614, in _execute_20
    return meth(self, args_10style, kwargs_10style, execution_options)
  File "/media/khalil-gazairly/aser/ITI/Flask/flask_todo/todo_env/lib/python3.8/site-packages/sqlalchemy/sql/elements.py", line 325, in _execute_on_connection
    return connection._execute_clauseelement(
  File "/media/khalil-gazairly/aser/ITI/Flask/flask_todo/todo_env/lib/python3.8/site-packages/sqlalchemy/engine/base.py", line 1481, in _execute_clauseelement
    ret = self._execute_context(
  File "/media/khalil-gazairly/aser/ITI/Flask/flask_todo/todo_env/lib/python3.8/site-packages/sqlalchemy/engine/base.py", line 1845, in _execute_context
    self._handle_dbapi_exception(
  File "/media/khalil-gazairly/aser/ITI/Flask/flask_todo/todo_env/lib/python3.8/site-packages/sqlalchemy/engine/base.py", line 2026, in _handle_dbapi_exception
    util.raise_(
  File "/media/khalil-gazairly/aser/ITI/Flask/flask_todo/todo_env/lib/python3.8/site-packages/sqlalchemy/util/compat.py", line 207, in raise_
    raise exception
  File "/media/khalil-gazairly/aser/ITI/Flask/flask_todo/todo_env/lib/python3.8/site-packages/sqlalchemy/engine/base.py", line 1802, in _execute_context
    self.dialect.do_execute(
  File "/media/khalil-gazairly/aser/ITI/Flask/flask_todo/todo_env/lib/python3.8/site-packages/sqlalchemy/engine/default.py", line 719, in do_execute
    cursor.execute(statement, parameters)
sqlalchemy.exc.IntegrityError: (sqlite3.IntegrityError) NOT NULL constraint failed: todo.name
[SQL: INSERT INTO todo (name, priority, description, finished, created_at) VALUES (?, ?, ?, ?, ?)]
[parameters: (None, '10', 'task 4444', 0, '2021-11-20 00:22:43.213543')]
(Background on this error at: https://sqlalche.me/e/14/gkpj)

During handling of the above exception, another exception occurred:

Traceback (most recent call last):
  File "/media/khalil-gazairly/aser/ITI/Flask/flask_todo/todo_env/lib/python3.8/site-packages/flask/app.py", line 1516, in full_dispatch_request
    rv = self.dispatch_request()
  File "/media/khalil-gazairly/aser/ITI/Flask/flask_todo/todo_env/lib/python3.8/site-packages/flask/app.py", line 1502, in dispatch_request
    return self.ensure_sync(self.view_functions[rule.endpoint])(**req.view_args)
  File "/media/khalil-gazairly/aser/ITI/Flask/flask_todo/todo_env/lib/python3.8/site-packages/flask_restful/__init__.py", line 467, in wrapper
    resp = resource(*args, **kwargs)
  File "/media/khalil-gazairly/aser/ITI/Flask/flask_todo/todo_env/lib/python3.8/site-packages/flask/views.py", line 84, in view
    return current_app.ensure_sync(self.dispatch_request)(*args, **kwargs)
  File "/media/khalil-gazairly/aser/ITI/Flask/flask_todo/todo_env/lib/python3.8/site-packages/flask_restful/__init__.py", line 582, in dispatch_request
    resp = meth(*args, **kwargs)
  File "/media/khalil-gazairly/aser/ITI/Flask/flask_todo/todo/app.py", line 79, in post
    abort(500, message='Internal Server Error')
  File "/media/khalil-gazairly/aser/ITI/Flask/flask_todo/todo_env/lib/python3.8/site-packages/flask_restful/__init__.py", line 31, in abort
    original_flask_abort(http_status_code)
  File "/media/khalil-gazairly/aser/ITI/Flask/flask_todo/todo_env/lib/python3.8/site-packages/werkzeug/exceptions.py", line 940, in abort
    _aborter(status, *args, **kwargs)
  File "/media/khalil-gazairly/aser/ITI/Flask/flask_todo/todo_env/lib/python3.8/site-packages/werkzeug/exceptions.py", line 923, in __call__
    raise self.mapping[code](*args, **kwargs)
werkzeug.exceptions.InternalServerError: 500 Internal Server Error: The server encountered an internal error and was unable to complete your request. Either the server is overloaded or there is an error in the application.
20-Nov-21 00:22:43 werkzeug - INFO - 127.0.0.1 - - [20/Nov/2021 00:22:43] "[35m[1mPOST /api/v1/todo HTTP/1.1[0m" 500 -
20-Nov-21 00:23:50 werkzeug - INFO -  * Detected change in '/media/khalil-gazairly/aser/ITI/Flask/flask_todo/todo/app.py', reloading
20-Nov-21 00:23:50 werkzeug - INFO -  * Restarting with stat
20-Nov-21 00:23:51 werkzeug - WARNING -  * Debugger is active!
20-Nov-21 00:23:51 werkzeug - INFO -  * Debugger PIN: 444-631-731
20-Nov-21 00:23:52 werkzeug - INFO - 127.0.0.1 - - [20/Nov/2021 00:23:52] "POST /api/v1/todo HTTP/1.1" 200 -
20-Nov-21 00:24:00 werkzeug - INFO - 127.0.0.1 - - [20/Nov/2021 00:24:00] "POST /api/v1/todo HTTP/1.1" 200 -
20-Nov-21 00:24:52 werkzeug - INFO -  * Detected change in '/media/khalil-gazairly/aser/ITI/Flask/flask_todo/todo/app.py', reloading
20-Nov-21 00:24:52 werkzeug - INFO -  * Restarting with stat
20-Nov-21 00:24:53 werkzeug - WARNING -  * Debugger is active!
20-Nov-21 00:24:53 werkzeug - INFO -  * Debugger PIN: 444-631-731
20-Nov-21 00:24:57 werkzeug - INFO - 127.0.0.1 - - [20/Nov/2021 00:24:57] "[35m[1mPOST /api/v1/todo HTTP/1.1[0m" 201 -
20-Nov-21 00:25:56 werkzeug - INFO -  * Detected change in '/media/khalil-gazairly/aser/ITI/Flask/flask_todo/todo/app.py', reloading
20-Nov-21 00:25:56 werkzeug - INFO -  * Restarting with stat
20-Nov-21 00:25:59 werkzeug - WARNING -  * Debugger is active!
20-Nov-21 00:25:59 werkzeug - INFO -  * Debugger PIN: 444-631-731
20-Nov-21 00:26:19 werkzeug - INFO - 127.0.0.1 - - [20/Nov/2021 00:26:19] "DELETE /api/v1/todo/1 HTTP/1.1" 200 -
20-Nov-21 00:26:31 werkzeug - INFO - 127.0.0.1 - - [20/Nov/2021 00:26:31] "DELETE /api/v1/todo/2 HTTP/1.1" 200 -
20-Nov-21 00:26:39 werkzeug - INFO - 127.0.0.1 - - [20/Nov/2021 00:26:39] "DELETE /api/v1/todo/3 HTTP/1.1" 200 -
20-Nov-21 00:26:51 werkzeug - INFO - 127.0.0.1 - - [20/Nov/2021 00:26:51] "[33mPOST /api/v1/todo/ HTTP/1.1[0m" 404 -
20-Nov-21 00:26:56 werkzeug - INFO - 127.0.0.1 - - [20/Nov/2021 00:26:56] "[35m[1mPOST /api/v1/todo HTTP/1.1[0m" 201 -
20-Nov-21 00:27:02 werkzeug - INFO - 127.0.0.1 - - [20/Nov/2021 00:27:02] "[35m[1mPOST /api/v1/todo HTTP/1.1[0m" 201 -
20-Nov-21 00:27:30 werkzeug - INFO - 127.0.0.1 - - [20/Nov/2021 00:27:30] "GET /api/v1/todo/1 HTTP/1.1" 200 -
20-Nov-21 00:27:55 werkzeug - INFO -  * Detected change in '/media/khalil-gazairly/aser/ITI/Flask/flask_todo/todo/app.py', reloading
20-Nov-21 00:27:55 werkzeug - INFO -  * Restarting with stat
20-Nov-21 00:27:59 werkzeug - WARNING -  * Debugger is active!
20-Nov-21 00:27:59 werkzeug - INFO -  * Debugger PIN: 444-631-731
